Workbook

Sheet data
A1: CoreType | B1: PartType | C1: Group | D1: ID | E1: Label | F1: Habitat | G1: DryMassTotal | H1: DryMassTC | I1: CarbonTC | J1: DryMassIC | K1: CarbonIC
A2: Small | B2: Leaves | C2: Natural | D2: NG 5 | E2: =CONCATENATE(SUBSTITUTE(D2, " ", "_"), "_", IF(B2 = "Leaves", "A", IF(B2 = "Roots", "B", NA))) -> NG_5_A | F2: =INDEX(raw!$B$2:$I$100,MATCH(data!D2,raw!$B$2:$B$108, 0), MATCH(data!F$1,raw!$B$1:$I$1, 0)) -> seagrass | G2: =IFERROR(INDEX(raw!$J$2:$K$86,MATCH(data!D2,raw!$B$2:$B$100,0),MATCH(data!B2,raw!$J$1:$K$1,0)), "NA") -> 780 | H2: =IF($F2 = "bare", 0, IFERROR(INDEX(carbon!$A$14:$J$93,MATCH("*"&$E2&"*",carbon!$A$14:$A$93,0),2), "NA")) -> 78.52 | I2: =IF($F2 = "bare", 0, IFERROR(INDEX(carbon!$A$14:$J$93,MATCH("*"&$E2&"*",carbon!$A$14:$A$93,0),4), "NA")) -> 24.32 | J2: =IF($F2 = "bare", 0, IFERROR(INDEX(carbon!$A$14:$J$93,MATCH("*"&$E2&"*",carbon!$A$14:$A$93,0),6), "NA")) -> 211.87 | K2: =IF($F2 = "bare", 0, IFERROR(INDEX(carbon!$A$14:$J$93,MATCH("*"&$E2&"*",carbon!$A$14:$A$93,0),8), "NA")) -> 2.318
A3: Small | B3: Roots | C3: Natural | D3: NG 5 | E3: =CONCATENATE(SUBSTITUTE(D3, " ", "_"), "_", IF(B3 = "Leaves", "A", IF(B3 = "Roots", "B", NA))) -> NG_5_B | F3: =INDEX(raw!$B$2:$I$100,MATCH(data!D3,raw!$B$2:$B$108, 0), MATCH(data!F$1,raw!$B$1:$I$1, 0)) -> seagrass | G3: =IFERROR(INDEX(raw!$J$2:$K$86,MATCH(data!D3,raw!$B$2:$B$100,0),MATCH(data!B3,raw!$J$1:$K$1,0)), "NA") -> 557 | H3: =IF($F3 = "bare", 0, IFERROR(INDEX(carbon!$A$14:$J$93,MATCH("*"&$E3&"*",carbon!$A$14:$A$93,0),2), "NA")) -> 70.52 | I3: =IF($F3 = "bare", 0, IFERROR(INDEX(carbon!$A$14:$J$93,MATCH("*"&$E3&"*",carbon!$A$14:$A$93,0),4), "NA")) -> 17.85 | J3: =IF($F3 = "bare", 0, IFERROR(INDEX(carbon!$A$14:$J$93,MATCH("*"&$E3&"*",carbon!$A$14:$A$93,0),6), "NA")) -> 189.89 | K3: =IF($F3 = "bare", 0, IFERROR(INDEX(carbon!$A$14:$J$93,MATCH("*"&$E3&"*",carbon!$A$14:$A$93,0),8), "NA")) -> 1.535
A4: Small | B4: Leaves | C4: Natural | D4: NG 6 | E4: =CONCATENATE(SUBSTITUTE(D4, " ", "_"), "_", IF(B4 = "Leaves", "A", IF(B4 = "Roots", "B", NA))) -> NG_6_A | F4: =INDEX(raw!$B$2:$I$100,MATCH(data!D4,raw!$B$2:$B$108, 0), MATCH(data!F$1,raw!$B$1:$I$1, 0)) -> seagrass | G4: =IFERROR(INDEX(raw!$J$2:$K$86,MATCH(data!D4,raw!$B$2:$B$100,0),MATCH(data!B4,raw!$J$1:$K$1,0)), "NA") -> 1415 | H4: =IF($F4 = "bare", 0, IFERROR(INDEX(carbon!$A$14:$J$93,MATCH("*"&$E4&"*",carbon!$A$14:$A$93,0),2), "NA")) -> NA | I4: =IF($F4 = "bare", 0, IFERROR(INDEX(carbon!$A$14:$J$93,MATCH("*"&$E4&"*",carbon!$A$14:$A$93,0),4), "NA")) -> NA | J4: =IF($F4 = "bare", 0, IFERROR(INDEX(carbon!$A$14:$J$93,MATCH("*"&$E4&"*",carbon!$A$14:$A$93,0),6), "NA")) -> NA | K4: =IF($F4 = "bare", 0, IFERROR(INDEX(carbon!$A$14:$J$93,MATCH("*"&$E4&"*",carbon!$A$14:$A$93,0),8), "NA")) -> NA
A5: Small | B5: Roots | C5: Natural | D5: NG 6 | E5: =CONCATENATE(SUBSTITUTE(D5, " ", "_"), "_", IF(B5 = "Leaves", "A", IF(B5 = "Roots", "B", NA))) -> NG_6_B | F5: =INDEX(raw!$B$2:$I$100,MATCH(data!D5,raw!$B$2:$B$108, 0), MATCH(data!F$1,raw!$B$1:$I$1, 0)) -> seagrass | G5: =IFERROR(INDEX(raw!$J$2:$K$86,MATCH(data!D5,raw!$B$2:$B$100,0),MATCH(data!B5,raw!$J$1:$K$1,0)), "NA") -> 833 | H5: =IF($F5 = "bare", 0, IFERROR(INDEX(carbon!$A$14:$J$93,MATCH("*"&$E5&"*",carbon!$A$14:$A$93,0),2), "NA")) -> NA | I5: =IF($F5 = "bare", 0, IFERROR(INDEX(carbon!$A$14:$J$93,MATCH("*"&$E5&"*",carbon!$A$14:$A$93,0),4), "NA")) -> NA | J5: =IF($F5 = "bare", 0, IFERROR(INDEX(carbon!$A$14:$J$93,MATCH("*"&$E5&"*",carbon!$A$14:$A$93,0),6), "NA")) -> NA | K5: =IF($F5 = "bare", 0, IFERROR(INDEX(carbon!$A$14:$J$93,MATCH("*"&$E5&"*",carbon!$A$14:$A$93,0),8), "NA")) -> NA
A6: Small | B6: Leaves | C6: Natural | D6: NG 7 | E6: =CONCATENATE(SUBSTITUTE(D6, " ", "_"), "_", IF(B6 = "Leaves", "A", IF(B6 = "Roots", "B", NA))) -> NG_7_A | F6: =INDEX(raw!$B$2:$I$100,MATCH(data!D6,raw!$B$2:$B$108, 0), MATCH(data!F$1,raw!$B$1:$I$1, 0)) -> seagrass | G6: =IFERROR(INDEX(raw!$J$2:$K$86,MATCH(data!D6,raw!$B$2:$B$100,0),MATCH(data!B6,raw!$J$1:$K$1,0)), "NA") -> 1552 | H6: =IF($F6 = "bare", 0, IFERROR(INDEX(carbon!$A$14:$J$93,MATCH("*"&$E6&"*",carbon!$A$14:$A$93,0),2), "NA")) -> NA | I6: =IF($F6 = "bare", 0, IFERROR(INDEX(carbon!$A$14:$J$93,MATCH("*"&$E6&"*",carbon!$A$14:$A$93,0),4), "NA")) -> NA | J6: =IF($F6 = "bare", 0, IFERROR(INDEX(carbon!$A$14:$J$93,MATCH("*"&$E6&"*",carbon!$A$14:$A$93,0),6), "NA")) -> NA | K6: =IF($F6 = "bare", 0, IFERROR(INDEX(carbon!$A$14:$J$93,MATCH("*"&$E6&"*",carbon!$A$14:$A$93,0),8), "NA")) -> NA
A7: Small | B7: Roots | C7: Natural | D7: NG 7 | E7: =CONCATENATE(SUBSTITUTE(D7, " ", "_"), "_", IF(B7 = "Leaves", "A", IF(B7 = "Roots", "B", NA))) -> NG_7_B | F7: =INDEX(raw!$B$2:$I$100,MATCH(data!D7,raw!$B$2:$B$108, 0), MATCH(data!F$1,raw!$B$1:$I$1, 0)) -> seagrass | G7: =IFERROR(INDEX(raw!$J$2:$K$86,MATCH(data!D7,raw!$B$2:$B$100,0),MATCH(data!B7,raw!$J$1:$K$1,0)), "NA") -> 561 | H7: =IF($F7 = "bare", 0, IFERROR(INDEX(carbon!$A$14:$J$93,MATCH("*"&$E7&"*",carbon!$A$14:$A$93,0),2), "NA")) -> NA | I7: =IF($F7 = "bare", 0, IFERROR(INDEX(carbon!$A$14:$J$93,MATCH("*"&$E7&"*",carbon!$A$14:$A$93,0),4), "NA")) -> NA | J7: =IF($F7 = "bare", 0, IFERROR(INDEX(carbon!$A$14:$J$93,MATCH("*"&$E7&"*",carbon!$A$14:$A$93,0),6), "NA")) -> NA | K7: =IF($F7 = "bare", 0, IFERROR(INDEX(carbon!$A$14:$J$93,MATCH("*"&$E7&"*",carbon!$A$14:$A$93,0),8), "NA")) -> NA
A8: Small | B8: Leaves | C8: Natural | D8: NG 8 | E8: =CONCATENATE(SUBSTITUTE(D8, " ", "_"), "_", IF(B8 = "Leaves", "A", IF(B8 = "Roots", "B", NA))) -> NG_8_A | F8: =INDEX(raw!$B$2:$I$100,MATCH(data!D8,raw!$B$2:$B$108, 0), MATCH(data!F$1,raw!$B$1:$I$1, 0)) -> seagrass | G8: =IFERROR(INDEX(raw!$J$2:$K$86,MATCH(data!D8,raw!$B$2:$B$100,0),MATCH(data!B8,raw!$J$1:$K$1,0)), "NA") -> 2799 | H8: =IF($F8 = "bare", 0, IFERROR(INDEX(carbon!$A$14:$J$93,MATCH("*"&$E8&"*",carbon!$A$14:$A$93,0),2), "NA")) -> 71.18 | I8: =IF($F8 = "bare", 0, IFERROR(INDEX(carbon!$A$14:$J$93,MATCH("*"&$E8&"*",carbon!$A$14:$A$93,0),4), "NA")) -> 20.43 | J8: =IF($F8 = "bare", 0, IFERROR(INDEX(carbon!$A$14:$J$93,MATCH("*"&$E8&"*",carbon!$A$14:$A$93,0),6), "NA")) -> 230.9 | K8: =IF($F8 = "bare", 0, IFERROR(INDEX(carbon!$A$14:$J$93,MATCH("*"&$E8&"*",carbon!$A$14:$A$93,0),8), "NA")) -> 1.368
A9: Small | B9: Roots | C9: Natural | D9: NG 8 | E9: =CONCATENATE(SUBSTITUTE(D9, " ", "_"), "_", IF(B9 = "Leaves", "A", IF(B9 = "Roots", "B", NA))) -> NG_8_B | F9: =INDEX(raw!$B$2:$I$100,MATCH(data!D9,raw!$B$2:$B$108, 0), MATCH(data!F$1,raw!$B$1:$I$1, 0)) -> seagrass | G9: =IFERROR(INDEX(raw!$J$2:$K$86,MATCH(data!D9,raw!$B$2:$B$100,0),MATCH(data!B9,raw!$J$1:$K$1,0)), "NA") -> 1299 | H9: =IF($F9 = "bare", 0, IFERROR(INDEX(carbon!$A$14:$J$93,MATCH("*"&$E9&"*",carbon!$A$14:$A$93,0),2), "NA")) -> 78.01 | I9: =IF($F9 = "bare", 0, IFERROR(INDEX(carbon!$A$14:$J$93,MATCH("*"&$E9&"*",carbon!$A$14:$A$93,0),4), "NA")) -> 20.02 | J9: =IF($F9 = "bare", 0, IFERROR(INDEX(carbon!$A$14:$J$93,MATCH("*"&$E9&"*",carbon!$A$14:$A$93,0),6), "NA")) -> 266.81 | K9: =IF($F9 = "bare", 0, IFERROR(INDEX(carbon!$A$14:$J$93,MATCH("*"&$E9&"*",carbon!$A$14:$A$93,0),8), "NA")) -> 1.075
A10: Small | B10: Leaves | C10: Natural | D10: NG 9 | E10: =CONCATENATE(SUBSTITUTE(D10, " ", "_"), "_", IF(B10 = "Leaves", "A", IF(B10 = "Roots", "B", NA))) -> NG_9_A | F10: =INDEX(raw!$B$2:$I$100,MATCH(data!D10,raw!$B$2:$B$108, 0), MATCH(data!F$1,raw!$B$1:$I$1, 0)) -> marsh | G10: =IFERROR(INDEX(raw!$J$2:$K$86,MATCH(data!D10,raw!$B$2:$B$100,0),MATCH(data!B10,raw!$J$1:$K$1,0)), "NA") -> NA | H10: =IF($F10 = "bare", 0, IFERROR(INDEX(carbon!$A$14:$J$93,MATCH("*"&$E10&"*",carbon!$A$14:$A$93,0),2), "NA")) -> NA | I10: =IF($F10 = "bare", 0, IFERROR(INDEX(carbon!$A$14:$J$93,MATCH("*"&$E10&"*",carbon!$A$14:$A$93,0),4), "NA")) -> NA | J10: =IF($F10 = "bare", 0, IFERROR(INDEX(carbon!$A$14:$J$93,MATCH("*"&$E10&"*",carbon!$A$14:$A$93,0),6), "NA")) -> NA | K10: =IF($F10 = "bare", 0, IFERROR(INDEX(carbon!$A$14:$J$93,MATCH("*"&$E10&"*",carbon!$A$14:$A$93,0),8), "NA")) -> NA
A11: Small | B11: Roots | C11: Natural | D11: NG 9 | E11: =CONCATENATE(SUBSTITUTE(D11, " ", "_"), "_", IF(B11 = "Leaves", "A", IF(B11 = "Roots", "B", NA))) -> NG_9_B | F11: =INDEX(raw!$B$2:$I$100,MATCH(data!D11,raw!$B$2:$B$108, 0), MATCH(data!F$1,raw!$B$1:$I$1, 0)) -> marsh | G11: =IFERROR(INDEX(raw!$J$2:$K$86,MATCH(data!D11,raw!$B$2:$B$100,0),MATCH(data!B11,raw!$J$1:$K$1,0)), "NA") -> NA | H11: =IF($F11 = "bare", 0, IFERROR(INDEX(carbon!$A$14:$J$93,MATCH("*"&$E11&"*",carbon!$A$14:$A$93,0),2), "NA")) -> NA | I11: =IF($F11 = "bare", 0, IFERROR(INDEX(carbon!$A$14:$J$93,MATCH("*"&$E11&"*",carbon!$A$14:$A$93,0),4), "NA")) -> NA | J11: =IF($F11 = "bare", 0, IFERROR(INDEX(carbon!$A$14:$J$93,MATCH("*"&$E11&"*",carbon!$A$14:$A$93,0),6), "NA")) -> NA | K11: =IF($F11 = "bare", 0, IFERROR(INDEX(carbon!$A$14:$J$93,MATCH("*"&$E11&"*",carbon!$A$14:$A$93,0),8), "NA")) -> NA
A12: Small | B12: Leaves | C12: Natural | D12: NG 10 | E12: =CONCATENATE(SUBSTITUTE(D12, " ", "_"), "_", IF(B12 = "Leaves", "A", IF(B12 = "Roots", "B", NA))) -> NG_10_A | F12: =INDEX(raw!$B$2:$I$100,MATCH(data!D12,raw!$B$2:$B$108, 0), MATCH(data!F$1,raw!$B$1:$I$1, 0)) -> seagrass | G12: =IFERROR(INDEX(raw!$J$2:$K$86,MATCH(data!D12,raw!$B$2:$B$100,0),MATCH(data!B12,raw!$J$1:$K$1,0)), "NA") -> 1476 | H12: =IF($F12 = "bare", 0, IFERROR(INDEX(carbon!$A$14:$J$93,MATCH("*"&$E12&"*",carbon!$A$14:$A$93,0),2), "NA")) -> NA | I12: =IF($F12 = "bare", 0, IFERROR(INDEX(carbon!$A$14:$J$93,MATCH("*"&$E12&"*",carbon!$A$14:$A$93,0),4), "NA")) -> NA | J12: =IF($F12 = "bare", 0, IFERROR(INDEX(carbon!$A$14:$J$93,MATCH("*"&$E12&"*",carbon!$A$14:$A$93,0),6), "NA")) -> NA | K12: =IF($F12 = "bare", 0, IFERROR(INDEX(carbon!$A$14:$J$93,MATCH("*"&$E12&"*",carbon!$A$14:$A$93,0),8), "NA")) -> NA
A13: Small | B13: Roots | C13: Natural | D13: NG 10 | E13: =CONCATENATE(SUBSTITUTE(D13, " ", "_"), "_", IF(B13 = "Leaves", "A", IF(B13 = "Roots", "B", NA))) -> NG_10_B | F13: =INDEX(raw!$B$2:$I$100,MATCH(data!D13,raw!$B$2:$B$108, 0), MATCH(data!F$1,raw!$B$1:$I$1, 0)) -> seagrass | G13: =IFERROR(INDEX(raw!$J$2:$K$86,MATCH(data!D13,raw!$B$2:$B$100,0),MATCH(data!B13,raw!$J$1:$K$1,0)), "NA") -> 1194 | H13: =IF($F13 = "bare", 0, IFERROR(INDEX(carbon!$A$14:$J$93,MATCH("*"&$E13&"*",carbon!$A$14:$A$93,0),2), "NA")) -> NA | I13: =IF($F13 = "bare", 0, IFERROR(INDEX(carbon!$A$14:$J$93,MATCH("*"&$E13&"*",carbon!$A$14:$A$93,0),4), "NA")) -> NA | J13: =IF($F13 = "bare", 0, IFERROR(INDEX(carbon!$A$14:$J$93,MATCH("*"&$E13&"*",carbon!$A$14:$A$93,0),6), "NA")) -> NA | K13: =IF($F13 = "bare", 0, IFERROR(INDEX(carbon!$A$14:$J$93,MATCH("*"&$E13&"*",carbon!$A$14:$A$93,0),8), "NA")) -> NA
... A199: Small | B199: Roots | C199: Rewilded | D199: RR 53 | E199: =CONCATENATE(SUBSTITUTE(D199, " ", "_"), "_", IF(B199 = "Leaves", "A", IF(B199 = "Roots", "B", NA))) -> RR_53_B | F199: =INDEX(raw!$B$2:$I$100,MATCH(data!D199,raw!$B$2:$B$108, 0), MATCH(data!F$1,raw!$B$1:$I$1, 0)) -> marsh | G199: =IFERROR(INDEX(raw!$J$2:$K$86,MATCH(data!D199,raw!$B$2:$B$100,0),MATCH(data!B199,raw!$J$1:$K$1,0)), "NA") -> NA | H199: =IF($F199 = "bare", 0, IFERROR(INDEX(carbon!$A$14:$J$93,MATCH("*"&$E199&"*",carbon!$A$14:$A$93,0),2), "NA")) -> NA | I199: =IF($F199 = "bare", 0, IFERROR(INDEX(carbon!$A$14:$J$93,MATCH("*"&$E199&"*",carbon!$A$14:$A$93,0),4), "NA")) -> NA | J199: =IF($F199 = "bare", 0, IFERROR(INDEX(carbon!$A$14:$J$93,MATCH("*"&$E199&"*",carbon!$A$14:$A$93,0),6), "NA")) -> NA | K199: =IF($F199 = "bare", 0, IFERROR(INDEX(carbon!$A$14:$J$93,MATCH("*"&$E199&"*",carbon!$A$14:$A$93,0),8), "NA")) -> NA

Sheet raw
A1: type | B1: name | C1: site | D1: longitude | E1: latitude | F1: poskey.benthos | G1: poskey.sediment | H1: picture | I1: habitat | J1: Leaves | K1: Roots | L1: sorting lab | M1: seagrass.cover.Laurant | N1: spectral camera | O1: remark
A2: grid | B2: RG 25 | C2: rewilded | D2: -8.6904504 | E2: 40.672106 | F2: 2025001 | G2: 2025048 | H2: P7150059 | I2: algae | J2: =VLOOKUP($F2,'seagrass biomass'!$G:$L,2,FALSE) -> 0 | K2: =VLOOKUP($F2,'seagrass biomass'!$G:$L,3,FALSE) -> 0 | L2: aveiro
A3: random | B3: RR 47 | C3: rewilded | D3: -8.6905032 | E3: 40.67236 | F3: 2025002 | G3: 2025043 | H3: P7150061 | I3: seagrass | J3: =VLOOKUP($F3,'seagrass biomass'!$G:$L,2,FALSE) -> 0 | K3: =VLOOKUP($F3,'seagrass biomass'!$G:$L,3,FALSE) -> 0 | L3: aveiro
A4: grid | B4: RG 17 | C4: rewilded | D4: -8.6909023 | E4: 40.672397 | F4: 2025003 | G4: 2025047 | H4: P7150062 | I4: seagrass | J4: =VLOOKUP($F4,'seagrass biomass'!$G:$L,2,FALSE) -> 315 | K4: =VLOOKUP($F4,'seagrass biomass'!$G:$L,3,FALSE) -> 250 | L4: aveiro | M4: no | N4: no
A5: grid | B5: RG 9 | C5: rewilded | D5: -8.6913541 | E5: 40.672687 | F5: 2025004 | G5: 2025041 | H5: P7150063 | I5: seagrass | J5: =VLOOKUP($F5,'seagrass biomass'!$G:$L,2,FALSE) -> 42 | K5: =VLOOKUP($F5,'seagrass biomass'!$G:$L,3,FALSE) -> 141 | L5: aveiro
A6: grid | B6: RG 1 | C6: rewilded | D6: -8.691806 | E6: 40.672978 | F6: 2025005 | G6: 2025050 | H6: P7150065 | I6: seagrass | J6: =VLOOKUP($F6,'seagrass biomass'!$G:$L,2,FALSE) -> 2222 | K6: =VLOOKUP($F6,'seagrass biomass'!$G:$L,3,FALSE) -> 939 | L6: aveiro
A7: grid | B7: RG 2 | C7: rewilded | D7: -8.6914241 | E7: 40.673322 | F7: 2025006 | G7: 2025059 | H7: P7150066 | I7: bare | J7: =VLOOKUP($F7,'seagrass biomass'!$G:$L,2,FALSE) -> 17 | K7: =VLOOKUP($F7,'seagrass biomass'!$G:$L,3,FALSE) -> 0 | L7: aveiro
A8: grid | B8: RG 10 | C8: rewilded | D8: -8.6909723 | E8: 40.673031 | F8: 2025007 | G8: 2025056 | H8: P7150067 | I8: algae | J8: =VLOOKUP($F8,'seagrass biomass'!$G:$L,2,FALSE) -> 0 | K8: =VLOOKUP($F8,'seagrass biomass'!$G:$L,3,FALSE) -> 0 | L8: aveiro
A9: random | B9: RR 41 | C9: rewilded | D9: -8.6906446 | E9: 40.672994 | F9: 2025008 | G9: 2025060 | H9: P7150068 | I9: seagrass | J9: =VLOOKUP($F9,'seagrass biomass'!$G:$L,2,FALSE) -> 2418 | K9: =VLOOKUP($F9,'seagrass biomass'!$G:$L,3,FALSE) -> 1706 | L9: aveiro
A10: random | B10: RR 40 | C10: rewilded | D10: -8.6908498 | E10: 40.672778 | F10: 2025009 | G10: 2025045 | H10: P7150069 | I10: seagrass | J10: =VLOOKUP($F10,'seagrass biomass'!$G:$L,2,FALSE) -> 1377 | K10: =VLOOKUP($F10,'seagrass biomass'!$G:$L,3,FALSE) -> 1864 | L10: aveiro
A11: grid | B11: RG 18 | C11: rewilded | D11: -8.6905204 | E11: 40.672741 | F11: 2025010 | G11: 2025049 | H11: P7150070 | I11: seagrass | J11: =VLOOKUP($F11,'seagrass biomass'!$G:$L,2,FALSE) -> 2797 | K11: =VLOOKUP($F11,'seagrass biomass'!$G:$L,3,FALSE) -> 1048 | L11: aveiro
A12: random | B12: RR 48 | C12: rewilded | D12: -8.6902337 | E12: 40.672737 | F12: 2025011 | G12: 2025042 | H12: P7150071 | I12: seagrass | J12: =VLOOKUP($F12,'seagrass biomass'!$G:$L,2,FALSE) -> 3628 | K12: =VLOOKUP($F12,'seagrass biomass'!$G:$L,3,FALSE) -> 977 | L12: aveiro
A13: random | B13: RR 49 | C13: rewilded | D13: -8.6897936 | E13: 40.67296 | F13: 2025012 | G13: 2025054 | H13: P7150072 | I13: bare | J13: =VLOOKUP($F13,'seagrass biomass'!$G:$L,2,FALSE) -> 0 | K13: =VLOOKUP($F13,'seagrass biomass'!$G:$L,3,FALSE) -> 0 | L13: aveiro
A14: grid | B14: RG 19 | C14: rewilded | D14: -8.6901386 | E14: 40.673085 | F14: 2025013 | G14: 2025046 | H14: P7150073 | I14: seagrass | J14: =VLOOKUP($F14,'seagrass biomass'!$G:$L,2,FALSE) -> 1701 | K14: =VLOOKUP($F14,'seagrass biomass'!$G:$L,3,FALSE) -> 1821 | L14: aveiro
A15: grid | B15: RG 11 | C15: rewilded | D15: -8.6905904 | E15: 40.673375 | F15: 2025014 | G15: 2025051 | H15: P7150074 | I15: algae | J15: =VLOOKUP($F15,'seagrass biomass'!$G:$L,2,FALSE) -> 0 | K15: =VLOOKUP($F15,'seagrass biomass'!$G:$L,3,FALSE) -> 0 | L15: aveiro
A16: random | B16: RR 34 | C16: rewilded | D16: -8.6906575 | E16: 40.67332 | F16: 2025015 | G16: 2025053 | H16: P7150075 | I16: algae | J16: =VLOOKUP($F16,'seagrass biomass'!$G:$L,2,FALSE) -> 31 | K16: =VLOOKUP($F16,'seagrass biomass'!$G:$L,3,FALSE) -> 189 | L16: aveiro
A17: grid | B17: RG 3 | C17: rewilded | D17: -8.6910423 | E17: 40.673666 | F17: 2025016 | G17: 2025044 | H17: P7150076 | I17: seagrass | J17: =VLOOKUP($F17,'seagrass biomass'!$G:$L,2,FALSE) -> 871 | K17: =VLOOKUP($F17,'seagrass biomass'!$G:$L,3,FALSE) -> 401 | L17: aveiro | O17: edge bare and seagrass
A18: grid | B18: RG 4 | C18: rewilded | D18: -8.6906604 | E18: 40.67401 | F18: 2025017 | G18: 2025055 | H18: P7150077 | I18: seagrass | J18: =VLOOKUP($F18,'seagrass biomass'!$G:$L,2,FALSE) -> 994 | K18: =VLOOKUP($F18,'seagrass biomass'!$G:$L,3,FALSE) -> 343 | L18: aveiro
A19: random | B19: RR 35 | C19: rewilded | D19: -8.6905265 | E19: 40.673644 | F19: 2025018 | G19: 20250? | H19: P7150078 | I19: seagrass | J19: =VLOOKUP($F19,'seagrass biomass'!$G:$L,2,FALSE) -> 2523 | K19: =VLOOKUP($F19,'seagrass biomass'!$G:$L,3,FALSE) -> 1219 | L19: aveiro
A20: grid | B20: RG 12 | C20: rewilded | D20: -8.6902085 | E20: 40.673719 | F20: 2025019 | G20: 2025052 | H20: Laurant | I20: seagrass | J20: =VLOOKUP($F20,'seagrass biomass'!$G:$L,2,FALSE) -> 2695 | K20: =VLOOKUP($F20,'seagrass biomass'!$G:$L,3,FALSE) -> 1160 | L20: aveiro | M20: 96 | N20: AVE0-AVE20 | O20: info spectral cam notes Laurant
A21: grid | B21: RG 21 | C21: rewilded | D21: -8.6893748 | E21: 40.673773 | F21: 2025020 | G21: 2025061 | H21: P7150079 | I21: bare | J21: =VLOOKUP($F21,'seagrass biomass'!$G:$L,2,FALSE) -> 0 | K21: =VLOOKUP($F21,'seagrass biomass'!$G:$L,3,FALSE) -> 0 | L21: aveiro
A22: random | B22: RR 43 | C22: rewilded | D22: -8.6895451 | E22: 40.673856 | F22: 2025021 | G22: 2025057 | H22: P7150080 | I22: seagrass | J22: =VLOOKUP($F22,'seagrass biomass'!$G:$L,2,FALSE) -> 933 | K22: =VLOOKUP($F22,'seagrass biomass'!$G:$L,3,FALSE) -> 750 | L22: aveiro
A23: random | B23: RR 44 | C23: rewilded | D23: -8.6896032 | E23: 40.674076 | F23: 2025022 | G23: 2025072 | H23: P7150081 | I23: algae | J23: =VLOOKUP($F23,'seagrass biomass'!$G:$L,2,FALSE) -> 85 | K23: =VLOOKUP($F23,'seagrass biomass'!$G:$L,3,FALSE) -> 719 | L23: aveiro
A24: grid | B24: RG 13 | C24: rewilded | D24: -8.6898267 | E24: 40.674063 | F24: 2025023 | G24: 2025075 | H24: P7150082 | I24: seagrass | J24: =VLOOKUP($F24,'seagrass biomass'!$G:$L,2,FALSE) -> 2790 | K24: =VLOOKUP($F24,'seagrass biomass'!$G:$L,3,FALSE) -> 888 | L24: aveiro | M24: 100 | N24: A1-A20
A25: random | B25: RR 36 | C25: rewilded | D25: -8.6902026 | E25: 40.674295 | F25: 2025024 | G25: 2025080 | H25: P7150083 | I25: seagrass | J25: =VLOOKUP($F25,'seagrass biomass'!$G:$L,2,FALSE) -> 2113 | K25: =VLOOKUP($F25,'seagrass biomass'!$G:$L,3,FALSE) -> 675 | L25: aveiro | M25: 100 | N25: AVE21-AVE40
A26: grid | B26: RG 5 | C26: rewilded | D26: -8.6902785 | E26: 40.674354 | F26: 2025025 | G26: 2025052? | H26: P7150084 | I26: seagrass | J26: =VLOOKUP($F26,'seagrass biomass'!$G:$L,2,FALSE) -> 2171 | K26: =VLOOKUP($F26,'seagrass biomass'!$G:$L,3,FALSE) -> 933 | L26: aveiro | M26: 100 | N26: AVE41-AVE60
A27: grid | B27: RG 6 | C27: rewilded | D27: -8.6898967 | E27: 40.674698 | F27: 2025026 | G27: 2025070 | H27: P7150085 | I27: bare | J27: =VLOOKUP($F27,'seagrass biomass'!$G:$L,2,FALSE) -> 0 | K27: =VLOOKUP($F27,'seagrass biomass'!$G:$L,3,FALSE) -> 0 | L27: aveiro | M27: 0 | N27: A21-A40
A28: random | B28: RR 37 | C28: rewilded | D28: -8.6895364 | E28: 40.674448 | F28: 2025027 | G28: 2025073 | H28: P7150086 | I28: algae | J28: =VLOOKUP($F28,'seagrass biomass'!$G:$L,2,FALSE) -> 39 | K28: =VLOOKUP($F28,'seagrass biomass'!$G:$L,3,FALSE) -> 161 | L28: aveiro
A29: grid | B29: RG 14 | C29: rewilded | D29: -8.6894448 | E29: 40.674407 | F29: 2025028 | G29: 2025063 | H29: P7150087 | I29: seagrass | J29: =VLOOKUP($F29,'seagrass biomass'!$G:$L,2,FALSE) -> 2715 | K29: =VLOOKUP($F29,'seagrass biomass'!$G:$L,3,FALSE) -> 1696 | L29: aveiro
A30: random | B30: RR 45 | C30: rewilded | D30: -8.6891629 | E30: 40.674483 | F30: 2025029 | G30: 2025079 | H30: P7150088 | I30: seagrass | J30: =VLOOKUP($F30,'seagrass biomass'!$G:$L,2,FALSE) -> 1294 | K30: =VLOOKUP($F30,'seagrass biomass'!$G:$L,3,FALSE) -> 454 | L30: aveiro | M30: 25 | N30: A161-A180
A31: grid | B31: RG 22 | C31: rewilded | D31: -8.6889929 | E31: 40.674117 | F31: 2025030 | G31: 2025078 | H31: P7150089 | I31: bare | J31: =VLOOKUP($F31,'seagrass biomass'!$G:$L,2,FALSE) -> 228 | K31: =VLOOKUP($F31,'seagrass biomass'!$G:$L,3,FALSE) -> 191 | L31: aveiro | M31: 50 | N31: A181-A200
A32: random | B32: RR 51 | C32: rewilded | D32: -8.6890769 | E32: 40.673988 | F32: 2025031 | G32: 2025074 | H32: P7150090 | I32: bare | J32: =VLOOKUP($F32,'seagrass biomass'!$G:$L,2,FALSE) -> 0 | K32: =VLOOKUP($F32,'seagrass biomass'!$G:$L,3,FALSE) -> 0 | L32: aveiro
A33: random | B33: RR 52 | C33: rewilded | D33: -8.6882517 | E33: 40.674107 | F33: 2025032 | G33: 2025066 | H33: P7150091 | I33: bare | J33: =VLOOKUP($F33,'seagrass biomass'!$G:$L,2,FALSE) -> 0 | K33: =VLOOKUP($F33,'seagrass biomass'!$G:$L,3,FALSE) -> 0 | L33: aveiro
A34: grid | B34: RG 31 | C34: rewilded | D34: -8.6881592 | E34: 40.67417 | F34: 2025033 | G34: 2025071 | H34: P7160092 | I34: bare | J34: =VLOOKUP($F34,'seagrass biomass'!$G:$L,2,FALSE) -> 0 | K34: =VLOOKUP($F34,'seagrass biomass'!$G:$L,3,FALSE) -> 0 | L34: aveiro
A35: grid | B35: RG 23 | C35: rewilded | D35: -8.6886111 | E35: 40.674461 | F35: 2025034 | G35: 2025110 | H35: P7160093 | I35: bare | J35: =VLOOKUP($F35,'seagrass biomass'!$G:$L,2,FALSE) -> 0 | K35: =VLOOKUP($F35,'seagrass biomass'!$G:$L,3,FALSE) -> 0 | L35: aveiro | M35: 0 | N35: A141-A160
A36: random | B36: RR 46 | C36: rewilded | D36: -8.6887206 | E36: 40.674762 | F36: 2025035 | G36: 2025100 | H36: P7160094 | I36: seagrass | J36: =VLOOKUP($F36,'seagrass biomass'!$G:$L,2,FALSE) -> 206.02 | K36: =VLOOKUP($F36,'seagrass biomass'!$G:$L,3,FALSE) -> 212.4 | L36: aveiro | M36: 40 | N36: A101-A120
A37: grid | B37: RG 16 | C37: rewilded | D37: -8.688681 | E37: 40.675095 | F37: 2025036 | G37: 2025096 | H37: P7160095 | I37: seagrass | J37: =VLOOKUP($F37,'seagrass biomass'!$G:$L,2,FALSE) -> 645 | K37: =VLOOKUP($F37,'seagrass biomass'!$G:$L,3,FALSE) -> 607 | L37: aveiro | M37: 50 | N37: A121-A140
A38: grid | B38: RG 15 | C38: rewilded | D38: -8.6890629 | E38: 40.674751 | F38: 2025037 | G38: 2025095 | H38: P7160096 | I38: seagrass | J38: =VLOOKUP($F38,'seagrass biomass'!$G:$L,2,FALSE) -> 1871 | K38: =VLOOKUP($F38,'seagrass biomass'!$G:$L,3,FALSE) -> 1585 | L38: aveiro
A39: random | B39: RR 38 | C39: rewilded | D39: -8.6893755 | E39: 40.674802 | F39: 2025038 | G39: 2025062 | H39: P7160102 | I39: seagrass | J39: =VLOOKUP($F39,'seagrass biomass'!$G:$L,2,FALSE) -> 1642 | K39: =VLOOKUP($F39,'seagrass biomass'!$G:$L,3,FALSE) -> 1381 | L39: aveiro
A40: grid | B40: RG 7 | C40: rewilded | D40: -8.6895148 | E40: 40.675042 | F40: 2025039 | G40: 20250? | H40: P7160103 | I40: bare | J40: =VLOOKUP($F40,'seagrass biomass'!$G:$L,2,FALSE) -> 0 | K40: =VLOOKUP($F40,'seagrass biomass'!$G:$L,3,FALSE) -> 0 | L40: aveiro | M40: 0 | N40: A41-A60
...

Sheet seagrass biomass
A1: teller | B1: Code | C1: poskey | D1: AB | E1: dry weight (mg) | F1: remark | G1: Average of dry weight (mg) | H1: Column Labels | O1: Aveiro 07/2025
A2: 149 | C2: 2025001 | D2: A | E2: =IFERROR(IF(VLOOKUP(B2,$O$5:$P$148,2) = "empty", 0, VLOOKUP(B2,$O$5:$P$148,2)), 0) -> 0 | F2: on picture no seagrass | G2: Row Labels | H2: A | I2: B | J2: (blank) | K2: Grand Total | O2: Oven 48h at 60°C | R2: A = Above ground biomass
A3: 150 | C3: 2025001 | D3: B | E3: =IFERROR(IF(VLOOKUP(B3,$O$5:$P$148,2) = "empty", 0, VLOOKUP(B3,$O$5:$P$148,2)), 0) -> 0 | F3: on picture no seagrass | G3: 2025003 | H3: 315 | I3: 250 | K3: 282.5 | R3: B= Belowground biomass
A4: 151 | C4: 2025002 | D4: A | E4: =IFERROR(IF(VLOOKUP(B4,$O$5:$P$148,2) = "empty", 0, VLOOKUP(B4,$O$5:$P$148,2)), 0) -> 0 | F4: on picture no seagrass | G4: 2025004 | H4: 42 | I4: 141 | K4: 91.5 | O4: Code | P4: dry weight (mg)
A5: 152 | C5: 2025002 | D5: B | E5: =IFERROR(IF(VLOOKUP(B5,$O$5:$P$148,2) = "empty", 0, VLOOKUP(B5,$O$5:$P$148,2)), 0) -> 0 | F5: on picture no seagrass | G5: 2025005 | H5: 2222 | I5: 939 | K5: 1580.5 | O5: 10A | P5: 2797 | R5: Seagrass leaves and Roots/Rhizomes
A6: 107 | B6: 3A | C6: 2025003 | D6: A | E6: =IFERROR(IF(VLOOKUP(B6,$O$5:$P$148,2) = "empty", 0, VLOOKUP(B6,$O$5:$P$148,2)), 0) -> 315 | G6: 2025006 | H6: 17 | I6: 0 | K6: 8.5 | O6: 10B | P6: 1048
A7: 108 | B7: 3B | C7: 2025003 | D7: B | E7: =IFERROR(IF(VLOOKUP(B7,$O$5:$P$148,2) = "empty", 0, VLOOKUP(B7,$O$5:$P$148,2)), 0) -> 250 | G7: 2025007 | H7: 0 | I7: 0 | K7: 0 | O7: 113AN | P7: 1876
A8: 111 | B8: 4A | C8: 2025004 | D8: A | E8: =IFERROR(IF(VLOOKUP(B8,$O$5:$P$148,2) = "empty", 0, VLOOKUP(B8,$O$5:$P$148,2)), 0) -> 42 | G8: 2025008 | H8: 2418 | I8: 1706 | K8: 2062 | O8: 113BN | P8: 608
A9: 112 | B9: 4B | C9: 2025004 | D9: B | E9: =IFERROR(IF(VLOOKUP(B9,$O$5:$P$148,2) = "empty", 0, VLOOKUP(B9,$O$5:$P$148,2)), 0) -> 141 | G9: 2025009 | H9: 1377 | I9: 1864 | K9: 1620.5 | O9: 115AN | P9: =3982-6.2 -> 3975.8
A10: 113 | B10: 5A | C10: 2025005 | D10: A | E10: =IFERROR(IF(VLOOKUP(B10,$O$5:$P$148,2) = "empty", 0, VLOOKUP(B10,$O$5:$P$148,2)), 0) -> 2222 | G10: 2025010 | H10: 2797 | I10: 1048 | K10: 1922.5 | O10: 115BN | P10: 2080
A11: 114 | B11: 5B | C11: 2025005 | D11: B | E11: =IFERROR(IF(VLOOKUP(B11,$O$5:$P$148,2) = "empty", 0, VLOOKUP(B11,$O$5:$P$148,2)), 0) -> 939 | G11: 2025011 | H11: 3628 | I11: 977 | K11: 2302.5 | O11: 116AN | P11: 3531
A12: 115 | B12: 6A | C12: 2025006 | D12: A | E12: =IFERROR(IF(VLOOKUP(B12,$O$5:$P$148,2) = "empty", 0, VLOOKUP(B12,$O$5:$P$148,2)), 0) -> 17 | G12: 2025012 | H12: 0 | I12: 0 | K12: 0 | O12: 116BN | P12: 2364
A13: 116 | B13: 6B | C13: 2025006 | D13: B | E13: =IFERROR(IF(VLOOKUP(B13,$O$5:$P$148,2) = "empty", 0, VLOOKUP(B13,$O$5:$P$148,2)), 0) -> 0 | G13: 2025013 | H13: 1701 | I13: 1821 | K13: 1761 | O13: 117AN | P13: 750
A14: 117 | B14: 7A | C14: 2025007 | D14: A | E14: =IFERROR(IF(VLOOKUP(B14,$O$5:$P$148,2) = "empty", 0, VLOOKUP(B14,$O$5:$P$148,2)), 0) -> 0 | G14: 2025014 | H14: 0 | I14: 0 | K14: 0 | O14: 117BN | P14: 345
A15: 118 | B15: 7B | C15: 2025007 | D15: B | E15: =IFERROR(IF(VLOOKUP(B15,$O$5:$P$148,2) = "empty", 0, VLOOKUP(B15,$O$5:$P$148,2)), 0) -> 0 | G15: 2025015 | H15: 31 | I15: 189 | K15: 110 | O15: 119A | P15: 754
A16: 135 | B16: 8A | C16: 2025008 | D16: A | E16: =IFERROR(IF(VLOOKUP(B16,$O$5:$P$148,2) = "empty", 0, VLOOKUP(B16,$O$5:$P$148,2)), 0) -> 2418 | G16: 2025016 | H16: 871 | I16: 401 | K16: 636 | O16: 119B | P16: 582
A17: 136 | B17: 8B | C17: 2025008 | D17: B | E17: =IFERROR(IF(VLOOKUP(B17,$O$5:$P$148,2) = "empty", 0, VLOOKUP(B17,$O$5:$P$148,2)), 0) -> 1706 | G17: 2025017 | H17: 994 | I17: 343 | K17: 668.5 | O17: 11A | P17: 3628
A18: 143 | B18: 9A | C18: 2025009 | D18: A | E18: =IFERROR(IF(VLOOKUP(B18,$O$5:$P$148,2) = "empty", 0, VLOOKUP(B18,$O$5:$P$148,2)), 0) -> 1377 | G18: 2025018 | H18: 2523 | I18: 1219 | K18: 1871 | O18: 11B | P18: 977
A19: 144 | B19: 9B | C19: 2025009 | D19: B | E19: =IFERROR(IF(VLOOKUP(B19,$O$5:$P$148,2) = "empty", 0, VLOOKUP(B19,$O$5:$P$148,2)), 0) -> 1864 | G19: 2025019 | H19: 2695 | I19: 1160 | K19: 1927.5 | O19: 120AN | P19: 12
A20: 1 | B20: 10A | C20: 2025010 | D20: A | E20: =IFERROR(IF(VLOOKUP(B20,$O$5:$P$148,2) = "empty", 0, VLOOKUP(B20,$O$5:$P$148,2)), 0) -> 2797 | G20: 2025021 | H20: 933 | I20: 750 | K20: 841.5 | O20: 120BN | P20: 118
A21: 2 | B21: 10B | C21: 2025010 | D21: B | E21: =IFERROR(IF(VLOOKUP(B21,$O$5:$P$148,2) = "empty", 0, VLOOKUP(B21,$O$5:$P$148,2)), 0) -> 1048 | G21: 2025022 | H21: 85 | I21: 719 | K21: 402 | O21: 121AN | P21: empty
A22: 13 | B22: 11A | C22: 2025011 | D22: A | E22: =IFERROR(IF(VLOOKUP(B22,$O$5:$P$148,2) = "empty", 0, VLOOKUP(B22,$O$5:$P$148,2)), 0) -> 3628 | G22: 2025023 | H22: 2790 | I22: 888 | K22: 1839 | O22: 121BN | P22: empty
A23: 14 | B23: 11B | C23: 2025011 | D23: B | E23: =IFERROR(IF(VLOOKUP(B23,$O$5:$P$148,2) = "empty", 0, VLOOKUP(B23,$O$5:$P$148,2)), 0) -> 977 | G23: 2025024 | H23: 2113 | I23: 675 | K23: 1394 | O23: 122AN | P23: 2650
A24: 33 | B24: 12A | C24: 2025012 | D24: A | E24: =IFERROR(IF(VLOOKUP(B24,$O$5:$P$148,2) = "empty", 0, VLOOKUP(B24,$O$5:$P$148,2)), 0) -> 0 | G24: 2025025 | H24: 2171 | I24: 933 | K24: 1552 | O24: 122BN | P24: 1147
A25: 34 | B25: 12B | C25: 2025012 | D25: B | E25: =IFERROR(IF(VLOOKUP(B25,$O$5:$P$148,2) = "empty", 0, VLOOKUP(B25,$O$5:$P$148,2)), 0) -> 0 | G25: 2025026 | H25: 0 | I25: 0 | K25: 0 | O25: 123AN | P25: empty
A26: 47 | B26: 13A | C26: 2025013 | D26: A | E26: =IFERROR(IF(VLOOKUP(B26,$O$5:$P$148,2) = "empty", 0, VLOOKUP(B26,$O$5:$P$148,2)), 0) -> 1701 | G26: 2025027 | H26: 39 | I26: 161 | K26: 100 | O26: 123BN | P26: empty
A27: 48 | B27: 13B | C27: 2025013 | D27: B | E27: =IFERROR(IF(VLOOKUP(B27,$O$5:$P$148,2) = "empty", 0, VLOOKUP(B27,$O$5:$P$148,2)), 0) -> 1821 | G27: 2025028 | H27: 2715 | I27: 1696 | K27: 2205.5 | O27: 124AN | P27: 2564
A28: 59 | B28: 14A | C28: 2025014 | D28: A | E28: =IFERROR(IF(VLOOKUP(B28,$O$5:$P$148,2) = "empty", 0, VLOOKUP(B28,$O$5:$P$148,2)), 0) -> 0 | G28: 2025029 | H28: 1294 | I28: 454 | K28: 874 | O28: 124BN | P28: 2102
A29: 60 | B29: 14B | C29: 2025014 | D29: B | E29: =IFERROR(IF(VLOOKUP(B29,$O$5:$P$148,2) = "empty", 0, VLOOKUP(B29,$O$5:$P$148,2)), 0) -> 0 | G29: 2025030 | H29: 228 | I29: 191 | K29: 209.5 | O29: 125AN | P29: 1891
A30: 65 | B30: 15A | C30: 2025015 | D30: A | E30: =IFERROR(IF(VLOOKUP(B30,$O$5:$P$148,2) = "empty", 0, VLOOKUP(B30,$O$5:$P$148,2)), 0) -> 31 | G30: 2025031 | H30: 0 | I30: 0 | K30: 0 | O30: 125BN | P30: 891
A31: 66 | B31: 15B | C31: 2025015 | D31: B | E31: =IFERROR(IF(VLOOKUP(B31,$O$5:$P$148,2) = "empty", 0, VLOOKUP(B31,$O$5:$P$148,2)), 0) -> 189 | G31: 2025034 | H31: 0 | I31: 0 | K31: 0 | O31: 126AN | P31: 2057
A32: 67 | B32: 16A | C32: 2025016 | D32: A | E32: =IFERROR(IF(VLOOKUP(B32,$O$5:$P$148,2) = "empty", 0, VLOOKUP(B32,$O$5:$P$148,2)), 0) -> 871 | G32: 2025035 | H32: 206.02 | I32: 212.4 | K32: 209.21 | O32: 126BN | P32: 1686
A33: 68 | B33: 16B | C33: 2025016 | D33: B | E33: =IFERROR(IF(VLOOKUP(B33,$O$5:$P$148,2) = "empty", 0, VLOOKUP(B33,$O$5:$P$148,2)), 0) -> 401 | G33: 2025036 | H33: 645 | I33: 607 | K33: 626 | O33: 127AN | P33: 926
A34: 69 | B34: 17A | C34: 2025017 | D34: A | E34: =IFERROR(IF(VLOOKUP(B34,$O$5:$P$148,2) = "empty", 0, VLOOKUP(B34,$O$5:$P$148,2)), 0) -> 994 | G34: 2025037 | H34: 1871 | I34: 1585 | K34: 1728 | O34: 127BN | P34: 1187
A35: 70 | B35: 17B | C35: 2025017 | D35: B | E35: =IFERROR(IF(VLOOKUP(B35,$O$5:$P$148,2) = "empty", 0, VLOOKUP(B35,$O$5:$P$148,2)), 0) -> 343 | G35: 2025038 | H35: 1642 | I35: 1381 | K35: 1511.5 | O35: 128AN | P35: 2434
A36: 71 | B36: 18A | C36: 2025018 | D36: A | E36: =IFERROR(IF(VLOOKUP(B36,$O$5:$P$148,2) = "empty", 0, VLOOKUP(B36,$O$5:$P$148,2)), 0) -> 2523 | G36: 2025040 | H36: 0 | I36: 0 | K36: 0 | O36: 128BN | P36: 1076
A37: 72 | B37: 18B | C37: 2025018 | D37: B | E37: =IFERROR(IF(VLOOKUP(B37,$O$5:$P$148,2) = "empty", 0, VLOOKUP(B37,$O$5:$P$148,2)), 0) -> 1219 | G37: 2025081 | H37: 2745 | I37: 1244 | K37: 1994.5 | O37: 12A | P37: empty
A38: 73 | B38: 19A | C38: 2025019 | D38: A | E38: =IFERROR(IF(VLOOKUP(B38,$O$5:$P$148,2) = "empty", 0, VLOOKUP(B38,$O$5:$P$148,2)), 0) -> 2695 | G38: 2025082 | H38: 400 | I38: 338 | K38: 369 | O38: 12B | P38: empty
A39: 74 | B39: 19B | C39: 2025019 | D39: B | E39: =IFERROR(IF(VLOOKUP(B39,$O$5:$P$148,2) = "empty", 0, VLOOKUP(B39,$O$5:$P$148,2)), 0) -> 1160 | G39: 2025084 | H39: 1514 | I39: 556 | K39: 1035 | O39: 130A | P39: empty
A40: 153 | C40: 2025020 | D40: A | E40: =IFERROR(IF(VLOOKUP(B40,$O$5:$P$148,2) = "empty", 0, VLOOKUP(B40,$O$5:$P$148,2)), 0) -> 0 | F40: on picture no seagrass | G40: 2025085 | H40: 2566 | I40: 1512 | K40: 2039 | O40: 130BN | P40: 125
...

Sheet carbon
D1: PLQ_LEE_LCE
D2: Formulaire de résultats
D3: DETERMINATION DU CARBONE TOTAL, ORGANIQUE ET INORGANIQUE DANS LES SOLS
A5: Opérateur :
A6: Date d'analyse :
A7: RE :
A8: Norme :
B10: Analyse du Carbone total | F10: Analyse du Carbone inorganique
A11: N° éch | B11: Prise d'essai humide (mg) | C11: Matière sèche (%) | D11: Masse C mesurée (mg) | E11: Concentration Ctot (g de C/kg de matière sèche) | F11: Prise d'essai humide (mg) | G11: Matière sèche (%) | H11: Concentration IC mesurée (mg) | I11: Concentration IC (g de C/kg de matière sèche) | J11: Concentration COT (g de C/kg de matière sèche)
E13: - | I13: - | J13: -
A14: NG_27_A * | B14: 78.55 | C14: 1 | D14: 23.34 | E14: =(D14*1000/B14)*C14 -> 297.13558 | F14: 187.41 | G14: 1 | H14: 1.737 | I14: =(H14*1000/F14)*G14 -> 9.2684489 | J14: =E14-I14 -> 287.86713
A15: NR_41_A | B15: 79.54 | C15: 1 | D15: 21.31 | E15: =(D15*1000/B15)*C15 -> 267.91551 | F15: 321.11 | G15: 1 | H15: 1.528 | I15: =(H15*1000/F15)*G15 -> 4.758494 | J15: =E15-I15 -> 263.15702
A16: NR_43_A | B16: 76 | C16: 1 | D16: 22.26 | E16: =(D16*1000/B16)*C16 -> 292.89474 | F16: 270.07 | G16: 1 | H16: 2.409 | I16: =(H16*1000/F16)*G16 -> 8.9199097 | J16: =E16-I16 -> 283.97483
A17: NR_49_A | B17: 78.48 | C17: 1 | D17: 22.57 | E17: =(D17*1000/B17)*C17 -> 287.58919 | F17: 282.15 | G17: 1 | H17: 1.135 | I17: =(H17*1000/F17)*G17 -> 4.022683 | J17: =E17-I17 -> 283.56651
A18: NR_51_A * | B18: 73.34 | C18: 1 | D18: 21.97 | E18: =(D18*1000/B18)*C18 -> 299.56368 | F18: 205.03 | G18: 1 | H18: 1.839 | I18: =(H18*1000/F18)*G18 -> 8.9694191 | J18: =E18-I18 -> 290.59426
A19: NR_52_A | B19: 71.32 | C19: 1 | D19: 20.49 | E19: =(D19*1000/B19)*C19 -> 287.29669 | F19: 251.3 | G19: 1 | H19: 1.516 | I19: =(H19*1000/F19)*G19 -> 6.0326303 | J19: =E19-I19 -> 281.26406
A21: NG_27_B | B21: 77.4 | C21: 1 | D21: 19.61 | E21: =(D21*1000/B21)*C21 -> 253.35917 | F21: 247.92 | G21: 1 | H21: 1.09 | I21: =(H21*1000/F21)*G21 -> 4.3965795 | J21: =E21-I21 -> 248.96259
A22: NR_41_B * | B22: 78.98 | C22: 1 | D22: 19.09 | E22: =(D22*1000/B22)*C22 -> 241.70676 | F22: 226.35 | G22: 1 | H22: 0.8794 | I22: =(H22*1000/F22)*G22 -> 3.8851336 | J22: =E22-I22 -> 237.82163
A23: NR_43_B | B23: 70.21 | C23: 1 | D23: 18.68 | E23: =(D23*1000/B23)*C23 -> 266.05897 | F23: 244.33 | G23: 1 | H23: 1.339 | I23: =(H23*1000/F23)*G23 -> 5.480293 | J23: =E23-I23 -> 260.57867
A24: NR_49_B | B24: 75.29 | C24: 1 | D24: 21.18 | E24: =(D24*1000/B24)*C24 -> 281.31226 | F24: 200.61 | G24: 1 | H24: 0.9385 | I24: =(H24*1000/F24)*G24 -> 4.6782314 | J24: =E24-I24 -> 276.63403
A25: NR_51_B | B25: 72.7 | C25: 1 | D25: 19.46 | E25: =(D25*1000/B25)*C25 -> 267.67538 | F25: 158.75 | G25: 1 | H25: 0.6689 | I25: =(H25*1000/F25)*G25 -> 4.2135433 | J25: =E25-I25 -> 263.46183
A26: NR_52_B | B26: 71.37 | C26: 1 | D26: 19.26 | E26: =(D26*1000/B26)*C26 -> 269.86129 | F26: 265.77 | G26: 1 | H26: 1.759 | I26: =(H26*1000/F26)*G26 -> 6.6185047 | J26: =E26-I26 -> 263.24278
... A92: RG_24_B | B92: 76.32 | C92: 1 | D92: 14.86 | E92: =(D92*1000/B92)*C92 -> 194.7065 | F92: 188.26 | G92: 1 | H92: 0 | I92: =(H92*1000/F92)*G92 -> 0 | J92: =E92-I92 -> 194.7065
A95: * Samples not well homogenised
