Workbook

Sheet data
A1: CoreType | B1: PartType | C1: Group | D1: ID | E1: Label | F1: Habitat | G1: DryMassTotal | H1: DryMassTC | I1: CarbonTC | J1: DryMassIC | K1: CarbonIC
A2: Small | B2: Leaves | C2: Low | D2: L_01 | E2: =CONCATENATE(D2, "_", IF(B2 = "Leaves", "A", IF(B2 = "Roots", "B", "NA"))) -> L_01_A | F2: seagrass | G2: =IFERROR(INDEX(biomass!$B$2:$C$61,MATCH(data!D2,biomass!$A$2:$A$61,0),MATCH(data!B2,biomass!$B$1:$C$1,0))*1000,"NA") -> 1181 | H2: =IF($F2= "bare", 0, IFERROR(INDEX(carbon!$A$14:$J$48,MATCH("*"&data!$E2&"*",carbon!$A$14:$A$48,0),2), "NA") ) -> NA | I2: =IF($F2= "bare", 0, IFERROR(INDEX(carbon!$A$14:$J$48,MATCH("*"&data!$E2&"*",carbon!$A$14:$A$48,0),4), "NA") ) -> NA | J2: =IF($F2= "bare", 0, IFERROR(INDEX(carbon!$A$14:$J$48,MATCH("*"&data!$E2&"*",carbon!$A$14:$A$48,0),6), "NA") ) -> NA | K2: =IF($F2= "bare", 0, IFERROR(INDEX(carbon!$A$14:$J$48,MATCH("*"&data!$E2&"*",carbon!$A$14:$A$48,0),8), "NA") ) -> NA
A3: Small | B3: Leaves | C3: Low | D3: L_02 | E3: =CONCATENATE(D3, "_", IF(B3 = "Leaves", "A", IF(B3 = "Roots", "B", "NA"))) -> L_02_A | F3: seagrass | G3: =IFERROR(INDEX(biomass!$B$2:$C$61,MATCH(data!D3,biomass!$A$2:$A$61,0),MATCH(data!B3,biomass!$B$1:$C$1,0))*1000,"NA") -> 1175 | H3: =IF($F3= "bare", 0, IFERROR(INDEX(carbon!$A$14:$J$48,MATCH("*"&data!$E3&"*",carbon!$A$14:$A$48,0),2), "NA") ) -> NA | I3: =IF($F3= "bare", 0, IFERROR(INDEX(carbon!$A$14:$J$48,MATCH("*"&data!$E3&"*",carbon!$A$14:$A$48,0),4), "NA") ) -> NA | J3: =IF($F3= "bare", 0, IFERROR(INDEX(carbon!$A$14:$J$48,MATCH("*"&data!$E3&"*",carbon!$A$14:$A$48,0),6), "NA") ) -> NA | K3: =IF($F3= "bare", 0, IFERROR(INDEX(carbon!$A$14:$J$48,MATCH("*"&data!$E3&"*",carbon!$A$14:$A$48,0),8), "NA") ) -> NA
A4: Small | B4: Leaves | C4: Low | D4: L_03 | E4: =CONCATENATE(D4, "_", IF(B4 = "Leaves", "A", IF(B4 = "Roots", "B", "NA"))) -> L_03_A | F4: seagrass | G4: =IFERROR(INDEX(biomass!$B$2:$C$61,MATCH(data!D4,biomass!$A$2:$A$61,0),MATCH(data!B4,biomass!$B$1:$C$1,0))*1000,"NA") -> 1909 | H4: =IF($F4= "bare", 0, IFERROR(INDEX(carbon!$A$14:$J$48,MATCH("*"&data!$E4&"*",carbon!$A$14:$A$48,0),2), "NA") ) -> NA | I4: =IF($F4= "bare", 0, IFERROR(INDEX(carbon!$A$14:$J$48,MATCH("*"&data!$E4&"*",carbon!$A$14:$A$48,0),4), "NA") ) -> NA | J4: =IF($F4= "bare", 0, IFERROR(INDEX(carbon!$A$14:$J$48,MATCH("*"&data!$E4&"*",carbon!$A$14:$A$48,0),6), "NA") ) -> NA | K4: =IF($F4= "bare", 0, IFERROR(INDEX(carbon!$A$14:$J$48,MATCH("*"&data!$E4&"*",carbon!$A$14:$A$48,0),8), "NA") ) -> NA
A5: Small | B5: Leaves | C5: Low | D5: L_04 | E5: =CONCATENATE(D5, "_", IF(B5 = "Leaves", "A", IF(B5 = "Roots", "B", "NA"))) -> L_04_A | F5: seagrass | G5: =IFERROR(INDEX(biomass!$B$2:$C$61,MATCH(data!D5,biomass!$A$2:$A$61,0),MATCH(data!B5,biomass!$B$1:$C$1,0))*1000,"NA") -> 894 | H5: =IF($F5= "bare", 0, IFERROR(INDEX(carbon!$A$14:$J$48,MATCH("*"&data!$E5&"*",carbon!$A$14:$A$48,0),2), "NA") ) -> NA | I5: =IF($F5= "bare", 0, IFERROR(INDEX(carbon!$A$14:$J$48,MATCH("*"&data!$E5&"*",carbon!$A$14:$A$48,0),4), "NA") ) -> NA | J5: =IF($F5= "bare", 0, IFERROR(INDEX(carbon!$A$14:$J$48,MATCH("*"&data!$E5&"*",carbon!$A$14:$A$48,0),6), "NA") ) -> NA | K5: =IF($F5= "bare", 0, IFERROR(INDEX(carbon!$A$14:$J$48,MATCH("*"&data!$E5&"*",carbon!$A$14:$A$48,0),8), "NA") ) -> NA
A6: Small | B6: Leaves | C6: Low | D6: L_05 | E6: =CONCATENATE(D6, "_", IF(B6 = "Leaves", "A", IF(B6 = "Roots", "B", "NA"))) -> L_05_A | F6: seagrass | G6: =IFERROR(INDEX(biomass!$B$2:$C$61,MATCH(data!D6,biomass!$A$2:$A$61,0),MATCH(data!B6,biomass!$B$1:$C$1,0))*1000,"NA") -> 931 | H6: =IF($F6= "bare", 0, IFERROR(INDEX(carbon!$A$14:$J$48,MATCH("*"&data!$E6&"*",carbon!$A$14:$A$48,0),2), "NA") ) -> NA | I6: =IF($F6= "bare", 0, IFERROR(INDEX(carbon!$A$14:$J$48,MATCH("*"&data!$E6&"*",carbon!$A$14:$A$48,0),4), "NA") ) -> NA | J6: =IF($F6= "bare", 0, IFERROR(INDEX(carbon!$A$14:$J$48,MATCH("*"&data!$E6&"*",carbon!$A$14:$A$48,0),6), "NA") ) -> NA | K6: =IF($F6= "bare", 0, IFERROR(INDEX(carbon!$A$14:$J$48,MATCH("*"&data!$E6&"*",carbon!$A$14:$A$48,0),8), "NA") ) -> NA
A7: Small | B7: Leaves | C7: Low | D7: L_06 | E7: =CONCATENATE(D7, "_", IF(B7 = "Leaves", "A", IF(B7 = "Roots", "B", "NA"))) -> L_06_A | F7: seagrass | G7: =IFERROR(INDEX(biomass!$B$2:$C$61,MATCH(data!D7,biomass!$A$2:$A$61,0),MATCH(data!B7,biomass!$B$1:$C$1,0))*1000,"NA") -> 812 | H7: =IF($F7= "bare", 0, IFERROR(INDEX(carbon!$A$14:$J$48,MATCH("*"&data!$E7&"*",carbon!$A$14:$A$48,0),2), "NA") ) -> NA | I7: =IF($F7= "bare", 0, IFERROR(INDEX(carbon!$A$14:$J$48,MATCH("*"&data!$E7&"*",carbon!$A$14:$A$48,0),4), "NA") ) -> NA | J7: =IF($F7= "bare", 0, IFERROR(INDEX(carbon!$A$14:$J$48,MATCH("*"&data!$E7&"*",carbon!$A$14:$A$48,0),6), "NA") ) -> NA | K7: =IF($F7= "bare", 0, IFERROR(INDEX(carbon!$A$14:$J$48,MATCH("*"&data!$E7&"*",carbon!$A$14:$A$48,0),8), "NA") ) -> NA
A8: Small | B8: Leaves | C8: Low | D8: L_07 | E8: =CONCATENATE(D8, "_", IF(B8 = "Leaves", "A", IF(B8 = "Roots", "B", "NA"))) -> L_07_A | F8: seagrass | G8: =IFERROR(INDEX(biomass!$B$2:$C$61,MATCH(data!D8,biomass!$A$2:$A$61,0),MATCH(data!B8,biomass!$B$1:$C$1,0))*1000,"NA") -> 815 | H8: =IF($F8= "bare", 0, IFERROR(INDEX(carbon!$A$14:$J$48,MATCH("*"&data!$E8&"*",carbon!$A$14:$A$48,0),2), "NA") ) -> NA | I8: =IF($F8= "bare", 0, IFERROR(INDEX(carbon!$A$14:$J$48,MATCH("*"&data!$E8&"*",carbon!$A$14:$A$48,0),4), "NA") ) -> NA | J8: =IF($F8= "bare", 0, IFERROR(INDEX(carbon!$A$14:$J$48,MATCH("*"&data!$E8&"*",carbon!$A$14:$A$48,0),6), "NA") ) -> NA | K8: =IF($F8= "bare", 0, IFERROR(INDEX(carbon!$A$14:$J$48,MATCH("*"&data!$E8&"*",carbon!$A$14:$A$48,0),8), "NA") ) -> NA
A9: Small | B9: Leaves | C9: Low | D9: L_08 | E9: =CONCATENATE(D9, "_", IF(B9 = "Leaves", "A", IF(B9 = "Roots", "B", "NA"))) -> L_08_A | F9: seagrass | G9: =IFERROR(INDEX(biomass!$B$2:$C$61,MATCH(data!D9,biomass!$A$2:$A$61,0),MATCH(data!B9,biomass!$B$1:$C$1,0))*1000,"NA") -> 730 | H9: =IF($F9= "bare", 0, IFERROR(INDEX(carbon!$A$14:$J$48,MATCH("*"&data!$E9&"*",carbon!$A$14:$A$48,0),2), "NA") ) -> NA | I9: =IF($F9= "bare", 0, IFERROR(INDEX(carbon!$A$14:$J$48,MATCH("*"&data!$E9&"*",carbon!$A$14:$A$48,0),4), "NA") ) -> NA | J9: =IF($F9= "bare", 0, IFERROR(INDEX(carbon!$A$14:$J$48,MATCH("*"&data!$E9&"*",carbon!$A$14:$A$48,0),6), "NA") ) -> NA | K9: =IF($F9= "bare", 0, IFERROR(INDEX(carbon!$A$14:$J$48,MATCH("*"&data!$E9&"*",carbon!$A$14:$A$48,0),8), "NA") ) -> NA
A10: Small | B10: Leaves | C10: Low | D10: L_09 | E10: =CONCATENATE(D10, "_", IF(B10 = "Leaves", "A", IF(B10 = "Roots", "B", "NA"))) -> L_09_A | F10: seagrass | G10: =IFERROR(INDEX(biomass!$B$2:$C$61,MATCH(data!D10,biomass!$A$2:$A$61,0),MATCH(data!B10,biomass!$B$1:$C$1,0))*1000,"NA") -> 807 | H10: =IF($F10= "bare", 0, IFERROR(INDEX(carbon!$A$14:$J$48,MATCH("*"&data!$E10&"*",carbon!$A$14:$A$48,0),2), "NA") ) -> NA | I10: =IF($F10= "bare", 0, IFERROR(INDEX(carbon!$A$14:$J$48,MATCH("*"&data!$E10&"*",carbon!$A$14:$A$48,0),4), "NA") ) -> NA | J10: =IF($F10= "bare", 0, IFERROR(INDEX(carbon!$A$14:$J$48,MATCH("*"&data!$E10&"*",carbon!$A$14:$A$48,0),6), "NA") ) -> NA | K10: =IF($F10= "bare", 0, IFERROR(INDEX(carbon!$A$14:$J$48,MATCH("*"&data!$E10&"*",carbon!$A$14:$A$48,0),8), "NA") ) -> NA
A11: Small | B11: Leaves | C11: Low | D11: L_10 | E11: =CONCATENATE(D11, "_", IF(B11 = "Leaves", "A", IF(B11 = "Roots", "B", "NA"))) -> L_10_A | F11: seagrass | G11: =IFERROR(INDEX(biomass!$B$2:$C$61,MATCH(data!D11,biomass!$A$2:$A$61,0),MATCH(data!B11,biomass!$B$1:$C$1,0))*1000,"NA") -> 1104 | H11: =IF($F11= "bare", 0, IFERROR(INDEX(carbon!$A$14:$J$48,MATCH("*"&data!$E11&"*",carbon!$A$14:$A$48,0),2), "NA") ) -> NA | I11: =IF($F11= "bare", 0, IFERROR(INDEX(carbon!$A$14:$J$48,MATCH("*"&data!$E11&"*",carbon!$A$14:$A$48,0),4), "NA") ) -> NA | J11: =IF($F11= "bare", 0, IFERROR(INDEX(carbon!$A$14:$J$48,MATCH("*"&data!$E11&"*",carbon!$A$14:$A$48,0),6), "NA") ) -> NA | K11: =IF($F11= "bare", 0, IFERROR(INDEX(carbon!$A$14:$J$48,MATCH("*"&data!$E11&"*",carbon!$A$14:$A$48,0),8), "NA") ) -> NA
A12: Small | B12: Leaves | C12: Low | D12: L_11 | E12: =CONCATENATE(D12, "_", IF(B12 = "Leaves", "A", IF(B12 = "Roots", "B", "NA"))) -> L_11_A | F12: seagrass | G12: =IFERROR(INDEX(biomass!$B$2:$C$61,MATCH(data!D12,biomass!$A$2:$A$61,0),MATCH(data!B12,biomass!$B$1:$C$1,0))*1000,"NA") -> 1503 | H12: =IF($F12= "bare", 0, IFERROR(INDEX(carbon!$A$14:$J$48,MATCH("*"&data!$E12&"*",carbon!$A$14:$A$48,0),2), "NA") ) -> NA | I12: =IF($F12= "bare", 0, IFERROR(INDEX(carbon!$A$14:$J$48,MATCH("*"&data!$E12&"*",carbon!$A$14:$A$48,0),4), "NA") ) -> NA | J12: =IF($F12= "bare", 0, IFERROR(INDEX(carbon!$A$14:$J$48,MATCH("*"&data!$E12&"*",carbon!$A$14:$A$48,0),6), "NA") ) -> NA | K12: =IF($F12= "bare", 0, IFERROR(INDEX(carbon!$A$14:$J$48,MATCH("*"&data!$E12&"*",carbon!$A$14:$A$48,0),8), "NA") ) -> NA
A13: Small | B13: Leaves | C13: Low | D13: L_12 | E13: =CONCATENATE(D13, "_", IF(B13 = "Leaves", "A", IF(B13 = "Roots", "B", "NA"))) -> L_12_A | F13: seagrass | G13: =IFERROR(INDEX(biomass!$B$2:$C$61,MATCH(data!D13,biomass!$A$2:$A$61,0),MATCH(data!B13,biomass!$B$1:$C$1,0))*1000,"NA") -> 774 | H13: =IF($F13= "bare", 0, IFERROR(INDEX(carbon!$A$14:$J$48,MATCH("*"&data!$E13&"*",carbon!$A$14:$A$48,0),2), "NA") ) -> NA | I13: =IF($F13= "bare", 0, IFERROR(INDEX(carbon!$A$14:$J$48,MATCH("*"&data!$E13&"*",carbon!$A$14:$A$48,0),4), "NA") ) -> NA | J13: =IF($F13= "bare", 0, IFERROR(INDEX(carbon!$A$14:$J$48,MATCH("*"&data!$E13&"*",carbon!$A$14:$A$48,0),6), "NA") ) -> NA | K13: =IF($F13= "bare", 0, IFERROR(INDEX(carbon!$A$14:$J$48,MATCH("*"&data!$E13&"*",carbon!$A$14:$A$48,0),8), "NA") ) -> NA
... A111: Small | B111: Roots | C111: High | D111: H_30 | E111: =CONCATENATE(D111, "_", IF(B111 = "Leaves", "A", IF(B111 = "Roots", "B", "NA"))) -> H_30_B | F111: seagrass | G111: =IFERROR(INDEX(biomass!$B$2:$C$61,MATCH(data!D111,biomass!$A$2:$A$61,0),MATCH(data!B111,biomass!$B$1:$C$1,0))*1000,"NA") -> 938.6 | H111: =IF($F111= "bare", 0, IFERROR(INDEX(carbon!$A$14:$J$48,MATCH("*"&data!$E111&"*",carbon!$A$14:$A$48,0),2), "NA") ) -> NA | I111: =IF($F111= "bare", 0, IFERROR(INDEX(carbon!$A$14:$J$48,MATCH("*"&data!$E111&"*",carbon!$A$14:$A$48,0),4), "NA") ) -> NA | J111: =IF($F111= "bare", 0, IFERROR(INDEX(carbon!$A$14:$J$48,MATCH("*"&data!$E111&"*",carbon!$A$14:$A$48,0),6), "NA") ) -> NA | K111: =IF($F111= "bare", 0, IFERROR(INDEX(carbon!$A$14:$J$48,MATCH("*"&data!$E111&"*",carbon!$A$14:$A$48,0),8), "NA") ) -> NA

Sheet biomass
A1: Station | B1: Leaves | C1: Roots | D1: imageR_SPC | E1: imageR_threshold | F1: remarks
A2: L_01 | B2: 1.181 | C2: 1.256 | D2: 87.28 | E2: 0.6 | F2: glint
A3: L_02 | B3: 1.175 | C3: 0.636 | D3: 96.31 | E3: 0.62
A4: L_03 | B4: 1.909 | C4: 0.832 | D4: 93.52 | E4: 0.7 | F4: cropped
A5: L_04 | B5: 0.894 | C5: 1.121 | D5: 73.97 | E5: 0.55 | F5: water (glint)
A6: L_05 | B6: 0.931 | C6: 1.666 | D6: 82.9 | E6: 0.57 | F6: water (glint)
A7: L_06 | B7: 0.812 | C7: 0.882 | D7: 82.44 | E7: 0.57 | F7: water (glint)
A8: L_07 | B8: 0.815 | C8: 0.322 | D8: 69.41 | E8: 0.55 | F8: water (glint)
A9: L_08 | B9: 0.73 | C9: 0.913 | D9: 74.46 | E9: 0.55 | F9: water (glint)
A10: L_09 | B10: 0.807 | C10: 0.42 | D10: 58.44 | E10: 0.53 | F10: water (glint)
A11: L_10 | B11: 1.104 | C11: 0.717 | D11: 92.84 | E11: 0.57 | F11: water (glint)
A12: L_11 | B12: 1.503 | C12: 1.169 | D12: 94.59 | E12: 0.6 | F12: water (glint)
A13: L_12 | B13: 0.774 | C13: 0.875 | D13: 63.13 | E13: 0.55 | F13: water (glint)
A14: L_13 | B14: 0.935 | C14: 1.17 | D14: 63.21 | E14: 0.55 | F14: water (glint)
A15: L_14 | B15: 0.882 | C15: 1.068 | D15: 77.6 | E15: 0.58 | F15: water (glint)
A16: L_15 | B16: 0.628 | C16: NA | D16: 70.92 | E16: 0.6
A17: L_16 | B17: 0.771 | C17: 0.609 | D17: 39.63 | E17: 0.5 | F17: cropped
A18: L_17 | B18: 0.626 | C18: 0.774 | D18: 41.81 | E18: 0.5 | F18: cropped
A19: L_18 | B19: 1.459 | C19: 1.259 | D19: 43.51 | E19: 0.53 | F19: cropped
A20: L_19 | B20: 0.691 | C20: 0.309 | D20: 42.66 | E20: 0.52 | F20: cropped; 0.53 would be better if not for the dark substrate
A21: L_20 | B21: 0.058 | C21: 0.108 | D21: 4.96 | E21: 0.4 | F21: cropped
A22: L_21 | B22: 0.718 | C22: 1.096 | D22: 50.31 | E22: 0.54 | F22: cropped
A23: L_22 | B23: 0.248 | C23: 0.512 | D23: 36.43 | E23: 0.6 | F23: cropped; dark subsurface substrate
A24: L_23 | B24: 0.249 | C24: 0.547 | D24: 51.57 | E24: 0.55 | F24: cropped
A25: L_24 | B25: 0.327 | C25: 0.326 | D25: 26.2 | E25: 0.51 | F25: cropped, muddy water distortion on lens
A26: L_25 | B26: 0.15 | C26: 0.229 | D26: 31.2 | E26: 0.63 | F26: cropped, water distortion on lens
A27: L_26 | B27: NA | C27: NA | D27: 34.67 | E27: 0.58 | F27: cropped, water distortion on lens
A28: L_27 | B28: 0 | C28: 0 | D28: 0 | E28: - | F28: bare
A29: L_28 | B29: 0 | C29: 0 | D29: 0.11 | E29: 0.32
A30: L_29 | B30: 0 | C30: 0 | D30: 0 | E30: - | F30: bare; no good threshold vs dark subsurface substrate
A31: L_30 | B31: 0 | C31: 0 | D31: 0.35 | E31: 0.45 | F31: cropped
A32: H_01 | B32: 1.495 | C32: 0.916 | D32: 92.54 | E32: 0.63
A33: H_02 | B33: 1.657 | C33: 1.845 | D33: 97.31 | E33: 0.75
A34: H_03 | B34: =1.86-0.004-0.0096 -> 1.8464 | C34: 1.748 | D34: 94.05 | E34: 0.7
A35: H_04 | B35: 0.151 | C35: 0.321 | D35: 37.91 | E35: 0.48
A36: H_05 | B36: 0.916 | C36: =1.369-0.0038 -> 1.3652 | D36: 49.4 | E36: 0.48
A37: H_06 | B37: 1.447 | C37: 1.457 | D37: 97.13 | E37: 0.74
A38: H_07 | B38: 1.287 | C38: 0.987 | D38: 94.22 | E38: 0.65
A39: H_08 | B39: 1.44 | C39: 1.339 | D39: 73.07 | E39: 0.6
A40: H_09 | B40: 1.766 | C40: 0.762 | D40: 93.31 | E40: 0.68
...

Sheet carbon
D1: PLQ_LEE_LCE
D2: Formulaire de résultats
D3: DETERMINATION DU CARBONE TOTAL, ORGANIQUE ET INORGANIQUE DANS LES SOLS
A5: Opérateur :
A6: Date d'analyse :
A7: RE :
A8: Norme :
B10: Analyse du Carbone total | F10: Analyse du Carbone inorganique
A11: N° éch | B11: Prise d'essai humide (mg) | C11: Matière sèche (%) | D11: Masse C mesurée (mg) | E11: Concentration Ctot (g de C/kg de matière sèche) | F11: Prise d'essai humide (mg) | G11: Matière sèche (%) | H11: Concentration IC mesurée (mg) | I11: Concentration IC (g de C/kg de matière sèche) | J11: Concentration COT (g de C/kg de matière sèche)
E13: - | I13: - | J13: -
A14: H_04_A/H_15_A/H_21_A/H_22_A/H_26_A | B14: 73.64 | C14: 1 | D14: 21.93 | E14: =(D14*1000/B14)*C14 -> 297.80011 | F14: 147.39 | G14: 1 | H14: 1.235 | I14: =(H14*1000/F14)*G14 -> 8.3791302 | J14: =E14-I14 -> 289.42098
A15: H_11_A | B15: 74.99 | C15: 1 | D15: 23.34 | E15: =(D15*1000/B15)*C15 -> 311.2415 | F15: 200.48 | G15: 1 | H15: 0.9779 | I15: =(H15*1000/F15)*G15 -> 4.8777933 | J15: =E15-I15 -> 306.36371
A16: H_12_A | B16: 79.02 | C16: 1 | D16: 24.62 | E16: =(D16*1000/B16)*C16 -> 311.56669 | F16: 205.94 | G16: 1 | H16: 1.312 | I16: =(H16*1000/F16)*G16 -> 6.3707876 | J16: =E16-I16 -> 305.1959
A18: H_04_B/H_15_B/H_21_B/H_22_B/H_26_B | B18: 73.95 | C18: 1 | D18: 19.45 | E18: =(D18*1000/B18)*C18 -> 263.01555 | F18: 225.17 | G18: 1 | H18: 0.2674 | I18: =(H18*1000/F18)*G18 -> 1.1875472 | J18: =E18-I18 -> 261.828
A19: H_11_B | B19: 71.16 | C19: 1 | D19: 19.61 | E19: =(D19*1000/B19)*C19 -> 275.57617 | F19: 212.83 | G19: 1 | H19: 0.8065 | I19: =(H19*1000/F19)*G19 -> 3.7894094 | J19: =E19-I19 -> 271.78676
A20: H_12_B | B20: 76.31 | C20: 1 | D20: 21.1 | E20: =(D20*1000/B20)*C20 -> 276.50373 | F20: 225.05 | G20: 1 | H20: 0.3501 | I20: =(H20*1000/F20)*G20 -> 1.5556543 | J20: =E20-I20 -> 274.94808
A22: H_19_A | B22: 72.75 | C22: 1 | D22: 25.56 | E22: =(D22*1000/B22)*C22 -> 351.34021 | F22: 201.84 | G22: 1 | H22: 2.166 | I22: =(H22*1000/F22)*G22 -> 10.731272 | J22: =E22-I22 -> 340.60893
A23: H_29_A | B23: 76.47 | C23: 1 | D23: 21.5 | E23: =(D23*1000/B23)*C23 -> 281.15601 | F23: 216.43 | G23: 1 | H23: 1.072 | I23: =(H23*1000/F23)*G23 -> 4.9531026 | J23: =E23-I23 -> 276.20291
A24: H_08_A | B24: 75.47 | C24: 1 | D24: 24.14 | E24: =(D24*1000/B24)*C24 -> 319.8622 | F24: 205.63 | G24: 1 | H24: 1.56 | I24: =(H24*1000/F24)*G24 -> 7.5864417 | J24: =E24-I24 -> 312.27576
A25: H_16_A | B25: 73.03 | C25: 1 | D25: 24.03 | E25: =(D25*1000/B25)*C25 -> 329.04286 | F25: 202.64 | G25: 1 | H25: 1.196 | I25: =(H25*1000/F25)*G25 -> 5.9020924 | J25: =E25-I25 -> 323.14077
A26: H_17_A | B26: 72.78 | C26: 1 | D26: 23.33 | E26: =(D26*1000/B26)*C26 -> 320.5551 | F26: 207.4 | G26: 1 | H26: 0.8868 | I26: =(H26*1000/F26)*G26 -> 4.2757956 | J26: =E26-I26 -> 316.2793
A27: H_23_A * | B27: 73.43 | C27: 1 | D27: 22.67 | E27: =(D27*1000/B27)*C27 -> 308.7294 | F27: 198.64 | G27: 1 | H27: 0.8351 | I27: =(H27*1000/F27)*G27 -> 4.2040878 | J27: =E27-I27 -> 304.52531
... A56: H_9 _B | B56: 75.84 | C56: 1 | D56: 20.21 | E56: =(D56*1000/B56)*C56 -> 266.48207 | F56: 204.62 | G56: 1 | H56: 0.7143 | I56: =(H56*1000/F56)*G56 -> 3.4908611 | J56: =E56-I56 -> 262.99121
A59: * Samples not well homogenised
