Workbook

Sheet data
A1: CoreType | B1: PartType | C1: Group | D1: ID | E1: Label | F1: Habitat | G1: DryMassTotal | H1: DryMassTC | I1: CarbonTC | J1: DryMassIC | K1: CarbonIC
A2: Small | B2: Leaves | C2: spc_100 | D2: 01 | E2: =CONCATENATE("Cadiz_2025_", IF(B2 = "Leaves", "L", IF(B2 = "Roots", "R", "NA")), "_", D2) -> Cadiz_2025_L_01 | F2: seagrass | G2: =IFERROR(VLOOKUP(CONCATENATE(E2, "_01"),raw!$E$2:$J$61,6)*1000, "NA") -> 8460 | H2: =IF($F2= "bare", 0, IFERROR(INDEX(carbon!$A$14:$J$48,MATCH("*"&data!$E2&"*",carbon!$A$14:$A$48,0),2), "NA") ) -> 97.99 | I2: =IF($F2= "bare", 0, IFERROR(INDEX(carbon!$A$14:$J$48,MATCH("*"&data!$E2&"*",carbon!$A$14:$A$48,0),4), "NA") ) -> 31.56 | J2: =IF($F2= "bare", 0, IFERROR(INDEX(carbon!$A$14:$J$48,MATCH("*"&data!$E2&"*",carbon!$A$14:$A$48,0),6), "NA") ) -> 315.6 | K2: =IF($F2= "bare", 0, IFERROR(INDEX(carbon!$A$14:$J$48,MATCH("*"&data!$E2&"*",carbon!$A$14:$A$48,0),8), "NA") ) -> 3.608
A3: Small | B3: Leaves | C3: spc_100 | D3: 02 | E3: =CONCATENATE("Cadiz_2025_", IF(B3 = "Leaves", "L", IF(B3 = "Roots", "R", "NA")), "_", D3) -> Cadiz_2025_L_02 | F3: seagrass | G3: =IFERROR(VLOOKUP(CONCATENATE(E3, "_01"),raw!$E$2:$J$61,6)*1000, "NA") -> 794 | H3: =IF($F3= "bare", 0, IFERROR(INDEX(carbon!$A$14:$J$48,MATCH("*"&data!$E3&"*",carbon!$A$14:$A$48,0),2), "NA") ) -> 70.47 | I3: =IF($F3= "bare", 0, IFERROR(INDEX(carbon!$A$14:$J$48,MATCH("*"&data!$E3&"*",carbon!$A$14:$A$48,0),4), "NA") ) -> 22.05 | J3: =IF($F3= "bare", 0, IFERROR(INDEX(carbon!$A$14:$J$48,MATCH("*"&data!$E3&"*",carbon!$A$14:$A$48,0),6), "NA") ) -> 351.92 | K3: =IF($F3= "bare", 0, IFERROR(INDEX(carbon!$A$14:$J$48,MATCH("*"&data!$E3&"*",carbon!$A$14:$A$48,0),8), "NA") ) -> 3.563
A4: Small | B4: Leaves | C4: spc_100 | D4: 03 | E4: =CONCATENATE("Cadiz_2025_", IF(B4 = "Leaves", "L", IF(B4 = "Roots", "R", "NA")), "_", D4) -> Cadiz_2025_L_03 | F4: seagrass | G4: =IFERROR(VLOOKUP(CONCATENATE(E4, "_01"),raw!$E$2:$J$61,6)*1000, "NA") -> 13930 | H4: =IF($F4= "bare", 0, IFERROR(INDEX(carbon!$A$14:$J$48,MATCH("*"&data!$E4&"*",carbon!$A$14:$A$48,0),2), "NA") ) -> 79.33 | I4: =IF($F4= "bare", 0, IFERROR(INDEX(carbon!$A$14:$J$48,MATCH("*"&data!$E4&"*",carbon!$A$14:$A$48,0),4), "NA") ) -> 23.98 | J4: =IF($F4= "bare", 0, IFERROR(INDEX(carbon!$A$14:$J$48,MATCH("*"&data!$E4&"*",carbon!$A$14:$A$48,0),6), "NA") ) -> 320.35 | K4: =IF($F4= "bare", 0, IFERROR(INDEX(carbon!$A$14:$J$48,MATCH("*"&data!$E4&"*",carbon!$A$14:$A$48,0),8), "NA") ) -> 2.636
A5: Small | B5: Leaves | C5: spc_100 | D5: 04 | E5: =CONCATENATE("Cadiz_2025_", IF(B5 = "Leaves", "L", IF(B5 = "Roots", "R", "NA")), "_", D5) -> Cadiz_2025_L_04 | F5: seagrass | G5: =IFERROR(VLOOKUP(CONCATENATE(E5, "_01"),raw!$E$2:$J$61,6)*1000, "NA") -> 8146 | H5: =IF($F5= "bare", 0, IFERROR(INDEX(carbon!$A$14:$J$48,MATCH("*"&data!$E5&"*",carbon!$A$14:$A$48,0),2), "NA") ) -> 73.99 | I5: =IF($F5= "bare", 0, IFERROR(INDEX(carbon!$A$14:$J$48,MATCH("*"&data!$E5&"*",carbon!$A$14:$A$48,0),4), "NA") ) -> 24.5 | J5: =IF($F5= "bare", 0, IFERROR(INDEX(carbon!$A$14:$J$48,MATCH("*"&data!$E5&"*",carbon!$A$14:$A$48,0),6), "NA") ) -> 281.98 | K5: =IF($F5= "bare", 0, IFERROR(INDEX(carbon!$A$14:$J$48,MATCH("*"&data!$E5&"*",carbon!$A$14:$A$48,0),8), "NA") ) -> 3.183
A6: Small | B6: Leaves | C6: spc_100 | D6: 05 | E6: =CONCATENATE("Cadiz_2025_", IF(B6 = "Leaves", "L", IF(B6 = "Roots", "R", "NA")), "_", D6) -> Cadiz_2025_L_05 | F6: seagrass | G6: =IFERROR(VLOOKUP(CONCATENATE(E6, "_01"),raw!$E$2:$J$61,6)*1000, "NA") -> 13270 | H6: =IF($F6= "bare", 0, IFERROR(INDEX(carbon!$A$14:$J$48,MATCH("*"&data!$E6&"*",carbon!$A$14:$A$48,0),2), "NA") ) -> 74.01 | I6: =IF($F6= "bare", 0, IFERROR(INDEX(carbon!$A$14:$J$48,MATCH("*"&data!$E6&"*",carbon!$A$14:$A$48,0),4), "NA") ) -> 18.35 | J6: =IF($F6= "bare", 0, IFERROR(INDEX(carbon!$A$14:$J$48,MATCH("*"&data!$E6&"*",carbon!$A$14:$A$48,0),6), "NA") ) -> 727.36 | K6: =IF($F6= "bare", 0, IFERROR(INDEX(carbon!$A$14:$J$48,MATCH("*"&data!$E6&"*",carbon!$A$14:$A$48,0),8), "NA") ) -> 6.267
A7: Small | B7: Leaves | C7: spc_100 | D7: 06 | E7: =CONCATENATE("Cadiz_2025_", IF(B7 = "Leaves", "L", IF(B7 = "Roots", "R", "NA")), "_", D7) -> Cadiz_2025_L_06 | F7: seagrass | G7: =IFERROR(VLOOKUP(CONCATENATE(E7, "_01"),raw!$E$2:$J$61,6)*1000, "NA") -> 7310 | H7: =IF($F7= "bare", 0, IFERROR(INDEX(carbon!$A$14:$J$48,MATCH("*"&data!$E7&"*",carbon!$A$14:$A$48,0),2), "NA") ) -> 68.98 | I7: =IF($F7= "bare", 0, IFERROR(INDEX(carbon!$A$14:$J$48,MATCH("*"&data!$E7&"*",carbon!$A$14:$A$48,0),4), "NA") ) -> 21.48 | J7: =IF($F7= "bare", 0, IFERROR(INDEX(carbon!$A$14:$J$48,MATCH("*"&data!$E7&"*",carbon!$A$14:$A$48,0),6), "NA") ) -> 657 | K7: =IF($F7= "bare", 0, IFERROR(INDEX(carbon!$A$14:$J$48,MATCH("*"&data!$E7&"*",carbon!$A$14:$A$48,0),8), "NA") ) -> 4.551
A8: Small | B8: Leaves | C8: spc_100 | D8: 07 | E8: =CONCATENATE("Cadiz_2025_", IF(B8 = "Leaves", "L", IF(B8 = "Roots", "R", "NA")), "_", D8) -> Cadiz_2025_L_07 | F8: seagrass | G8: =IFERROR(VLOOKUP(CONCATENATE(E8, "_01"),raw!$E$2:$J$61,6)*1000, "NA") -> 10270 | H8: =IF($F8= "bare", 0, IFERROR(INDEX(carbon!$A$14:$J$48,MATCH("*"&data!$E8&"*",carbon!$A$14:$A$48,0),2), "NA") ) -> 73.85 | I8: =IF($F8= "bare", 0, IFERROR(INDEX(carbon!$A$14:$J$48,MATCH("*"&data!$E8&"*",carbon!$A$14:$A$48,0),4), "NA") ) -> 22.28 | J8: =IF($F8= "bare", 0, IFERROR(INDEX(carbon!$A$14:$J$48,MATCH("*"&data!$E8&"*",carbon!$A$14:$A$48,0),6), "NA") ) -> 334.55 | K8: =IF($F8= "bare", 0, IFERROR(INDEX(carbon!$A$14:$J$48,MATCH("*"&data!$E8&"*",carbon!$A$14:$A$48,0),8), "NA") ) -> 2.835
A9: Small | B9: Leaves | C9: spc_100 | D9: 08 | E9: =CONCATENATE("Cadiz_2025_", IF(B9 = "Leaves", "L", IF(B9 = "Roots", "R", "NA")), "_", D9) -> Cadiz_2025_L_08 | F9: seagrass | G9: =IFERROR(VLOOKUP(CONCATENATE(E9, "_01"),raw!$E$2:$J$61,6)*1000, "NA") -> 8690 | H9: =IF($F9= "bare", 0, IFERROR(INDEX(carbon!$A$14:$J$48,MATCH("*"&data!$E9&"*",carbon!$A$14:$A$48,0),2), "NA") ) -> 74.85 | I9: =IF($F9= "bare", 0, IFERROR(INDEX(carbon!$A$14:$J$48,MATCH("*"&data!$E9&"*",carbon!$A$14:$A$48,0),4), "NA") ) -> 24.41 | J9: =IF($F9= "bare", 0, IFERROR(INDEX(carbon!$A$14:$J$48,MATCH("*"&data!$E9&"*",carbon!$A$14:$A$48,0),6), "NA") ) -> 260.41 | K9: =IF($F9= "bare", 0, IFERROR(INDEX(carbon!$A$14:$J$48,MATCH("*"&data!$E9&"*",carbon!$A$14:$A$48,0),8), "NA") ) -> 3.074
A10: Small | B10: Leaves | C10: spc_100 | D10: 09 | E10: =CONCATENATE("Cadiz_2025_", IF(B10 = "Leaves", "L", IF(B10 = "Roots", "R", "NA")), "_", D10) -> Cadiz_2025_L_09 | F10: seagrass | G10: =IFERROR(VLOOKUP(CONCATENATE(E10, "_01"),raw!$E$2:$J$61,6)*1000, "NA") -> 9430 | H10: =IF($F10= "bare", 0, IFERROR(INDEX(carbon!$A$14:$J$48,MATCH("*"&data!$E10&"*",carbon!$A$14:$A$48,0),2), "NA") ) -> 68.45 | I10: =IF($F10= "bare", 0, IFERROR(INDEX(carbon!$A$14:$J$48,MATCH("*"&data!$E10&"*",carbon!$A$14:$A$48,0),4), "NA") ) -> 23.24 | J10: =IF($F10= "bare", 0, IFERROR(INDEX(carbon!$A$14:$J$48,MATCH("*"&data!$E10&"*",carbon!$A$14:$A$48,0),6), "NA") ) -> 292.9 | K10: =IF($F10= "bare", 0, IFERROR(INDEX(carbon!$A$14:$J$48,MATCH("*"&data!$E10&"*",carbon!$A$14:$A$48,0),8), "NA") ) -> 2.928
A11: Small | B11: Leaves | C11: spc_50 | D11: 10 | E11: =CONCATENATE("Cadiz_2025_", IF(B11 = "Leaves", "L", IF(B11 = "Roots", "R", "NA")), "_", D11) -> Cadiz_2025_L_10 | F11: seagrass | G11: =IFERROR(VLOOKUP(CONCATENATE(E11, "_01"),raw!$E$2:$J$61,6)*1000, "NA") -> 920 | H11: =IF($F11= "bare", 0, IFERROR(INDEX(carbon!$A$14:$J$48,MATCH("*"&data!$E11&"*",carbon!$A$14:$A$48,0),2), "NA") ) -> 72.59 | I11: =IF($F11= "bare", 0, IFERROR(INDEX(carbon!$A$14:$J$48,MATCH("*"&data!$E11&"*",carbon!$A$14:$A$48,0),4), "NA") ) -> 16.37 | J11: =IF($F11= "bare", 0, IFERROR(INDEX(carbon!$A$14:$J$48,MATCH("*"&data!$E11&"*",carbon!$A$14:$A$48,0),6), "NA") ) -> 590.16 | K11: =IF($F11= "bare", 0, IFERROR(INDEX(carbon!$A$14:$J$48,MATCH("*"&data!$E11&"*",carbon!$A$14:$A$48,0),8), "NA") ) -> 4.294
A12: Small | B12: Leaves | C12: spc_50 | D12: 11 | E12: =CONCATENATE("Cadiz_2025_", IF(B12 = "Leaves", "L", IF(B12 = "Roots", "R", "NA")), "_", D12) -> Cadiz_2025_L_11 | F12: seagrass | G12: =IFERROR(VLOOKUP(CONCATENATE(E12, "_01"),raw!$E$2:$J$61,6)*1000, "NA") -> 722 | H12: =IF($F12= "bare", 0, IFERROR(INDEX(carbon!$A$14:$J$48,MATCH("*"&data!$E12&"*",carbon!$A$14:$A$48,0),2), "NA") ) -> 75.22 | I12: =IF($F12= "bare", 0, IFERROR(INDEX(carbon!$A$14:$J$48,MATCH("*"&data!$E12&"*",carbon!$A$14:$A$48,0),4), "NA") ) -> 23.63 | J12: =IF($F12= "bare", 0, IFERROR(INDEX(carbon!$A$14:$J$48,MATCH("*"&data!$E12&"*",carbon!$A$14:$A$48,0),6), "NA") ) -> 349 | K12: =IF($F12= "bare", 0, IFERROR(INDEX(carbon!$A$14:$J$48,MATCH("*"&data!$E12&"*",carbon!$A$14:$A$48,0),8), "NA") ) -> 3.524
A13: Small | B13: Leaves | C13: spc_50 | D13: 12 | E13: =CONCATENATE("Cadiz_2025_", IF(B13 = "Leaves", "L", IF(B13 = "Roots", "R", "NA")), "_", D13) -> Cadiz_2025_L_12 | F13: seagrass | G13: =IFERROR(VLOOKUP(CONCATENATE(E13, "_01"),raw!$E$2:$J$61,6)*1000, "NA") -> 594 | H13: =IF($F13= "bare", 0, IFERROR(INDEX(carbon!$A$14:$J$48,MATCH("*"&data!$E13&"*",carbon!$A$14:$A$48,0),2), "NA") ) -> 76.19 | I13: =IF($F13= "bare", 0, IFERROR(INDEX(carbon!$A$14:$J$48,MATCH("*"&data!$E13&"*",carbon!$A$14:$A$48,0),4), "NA") ) -> 22.04 | J13: =IF($F13= "bare", 0, IFERROR(INDEX(carbon!$A$14:$J$48,MATCH("*"&data!$E13&"*",carbon!$A$14:$A$48,0),6), "NA") ) -> 298.7 | K13: =IF($F13= "bare", 0, IFERROR(INDEX(carbon!$A$14:$J$48,MATCH("*"&data!$E13&"*",carbon!$A$14:$A$48,0),8), "NA") ) -> 3.575
... A61: Small | B61: Roots | C61: NA | D61: 30 | E61: =CONCATENATE("Cadiz_2025_", IF(B61 = "Leaves", "L", IF(B61 = "Roots", "R", "NA")), "_", D61) -> Cadiz_2025_R_30 | F61: NA | G61: =IFERROR(VLOOKUP(CONCATENATE(E61, "_01"),raw!$E$2:$J$61,6)*1000, "NA") -> NA | H61: =IF($F61= "bare", 0, IFERROR(INDEX(carbon!$A$14:$J$48,MATCH("*"&data!$E61&"*",carbon!$A$14:$A$48,0),2), "NA") ) -> NA | I61: =IF($F61= "bare", 0, IFERROR(INDEX(carbon!$A$14:$J$48,MATCH("*"&data!$E61&"*",carbon!$A$14:$A$48,0),4), "NA") ) -> NA | J61: =IF($F61= "bare", 0, IFERROR(INDEX(carbon!$A$14:$J$48,MATCH("*"&data!$E61&"*",carbon!$A$14:$A$48,0),6), "NA") ) -> NA | K61: =IF($F61= "bare", 0, IFERROR(INDEX(carbon!$A$14:$J$48,MATCH("*"&data!$E61&"*",carbon!$A$14:$A$48,0),8), "NA") ) -> NA

Sheet raw
A1: Core Type | B1: Group | C1: Sample | D1: SubSample | E1: SampleID | F1: Aluminium tare | G1: mass before oven | H1: mass after oven | I1: Fresh mass (g) | J1: Dry mass (g) | K1: Mass use for TC (mg) | L1: Mass TC (mg) | M1: Mass use for IC (mg) | N1: Mass IC (mg)
A2: Small | B2: Leaves | C2: 01 | D2: 01 | E2: Cadiz_2025_L_01_01 | F2: 2.76 | G2: 93.82 | H2: 11.22 | I2: =+G2-F2 -> 91.06 | J2: =IFERROR(+H2-F2, "NA") -> 8.46 | K2: =IFERROR(INDEX(carbon!$A$14:$J$48,MATCH(data!$E2,carbon!$A$14:$A$48,0),2), "NA") -> 97.99 | L2: =IFERROR(INDEX(carbon!$A$14:$J$48,MATCH(data!$E2,carbon!$A$14:$A$48,0),4), "NA") -> 31.56 | M2: =IFERROR(INDEX(carbon!$A$14:$J$48,MATCH(data!$E2,carbon!$A$14:$A$48,0),6), "NA") -> 315.6 | N2: =IFERROR(INDEX(carbon!$A$14:$J$48,MATCH(data!$E2,carbon!$A$14:$A$48,0),8), "NA") -> 3.608
A3: Small | B3: Leaves | C3: 02 | D3: 01 | E3: Cadiz_2025_L_02_01 | F3: 0.707 | G3: 93.39 | H3: 1.501 | I3: =+G3-F3 -> 92.683 | J3: =IFERROR(+H3-F3, "NA") -> 0.794 | K3: =IFERROR(INDEX(carbon!$A$14:$J$48,MATCH(data!$E3,carbon!$A$14:$A$48,0),2), "NA") -> 70.47 | L3: =IFERROR(INDEX(carbon!$A$14:$J$48,MATCH(data!$E3,carbon!$A$14:$A$48,0),4), "NA") -> 22.05 | M3: =IFERROR(INDEX(carbon!$A$14:$J$48,MATCH(data!$E3,carbon!$A$14:$A$48,0),6), "NA") -> 351.92 | N3: =IFERROR(INDEX(carbon!$A$14:$J$48,MATCH(data!$E3,carbon!$A$14:$A$48,0),8), "NA") -> 3.563
A4: Small | B4: Leaves | C4: 03 | D4: 01 | E4: Cadiz_2025_L_03_01 | F4: 5.74 | G4: 156.29 | H4: 19.67 | I4: =+G4-F4 -> 150.55 | J4: =IFERROR(+H4-F4, "NA") -> 13.93 | K4: =IFERROR(INDEX(carbon!$A$14:$J$48,MATCH(data!$E4,carbon!$A$14:$A$48,0),2), "NA") -> 79.33 | L4: =IFERROR(INDEX(carbon!$A$14:$J$48,MATCH(data!$E4,carbon!$A$14:$A$48,0),4), "NA") -> 23.98 | M4: =IFERROR(INDEX(carbon!$A$14:$J$48,MATCH(data!$E4,carbon!$A$14:$A$48,0),6), "NA") -> 320.35 | N4: =IFERROR(INDEX(carbon!$A$14:$J$48,MATCH(data!$E4,carbon!$A$14:$A$48,0),8), "NA") -> 2.636
A5: Small | B5: Leaves | C5: 04 | D5: 01 | E5: Cadiz_2025_L_04_01 | F5: 1.904 | G5: 94.82 | H5: 10.05 | I5: =+G5-F5 -> 92.916 | J5: =IFERROR(+H5-F5, "NA") -> 8.146 | K5: =IFERROR(INDEX(carbon!$A$14:$J$48,MATCH(data!$E5,carbon!$A$14:$A$48,0),2), "NA") -> 73.99 | L5: =IFERROR(INDEX(carbon!$A$14:$J$48,MATCH(data!$E5,carbon!$A$14:$A$48,0),4), "NA") -> 24.5 | M5: =IFERROR(INDEX(carbon!$A$14:$J$48,MATCH(data!$E5,carbon!$A$14:$A$48,0),6), "NA") -> 281.98 | N5: =IFERROR(INDEX(carbon!$A$14:$J$48,MATCH(data!$E5,carbon!$A$14:$A$48,0),8), "NA") -> 3.183
A6: Small | B6: Leaves | C6: 05 | D6: 01 | E6: Cadiz_2025_L_05_01 | F6: 1.91 | G6: 118.21 | H6: 15.18 | I6: =+G6-F6 -> 116.3 | J6: =IFERROR(+H6-F6, "NA") -> 13.27 | K6: =IFERROR(INDEX(carbon!$A$14:$J$48,MATCH(data!$E6,carbon!$A$14:$A$48,0),2), "NA") -> 74.01 | L6: =IFERROR(INDEX(carbon!$A$14:$J$48,MATCH(data!$E6,carbon!$A$14:$A$48,0),4), "NA") -> 18.35 | M6: =IFERROR(INDEX(carbon!$A$14:$J$48,MATCH(data!$E6,carbon!$A$14:$A$48,0),6), "NA") -> 727.36 | N6: =IFERROR(INDEX(carbon!$A$14:$J$48,MATCH(data!$E6,carbon!$A$14:$A$48,0),8), "NA") -> 6.267
A7: Small | B7: Leaves | C7: 06 | D7: 01 | E7: Cadiz_2025_L_06_01 | F7: 5.8 | G7: 95.31 | H7: 13.11 | I7: =+G7-F7 -> 89.51 | J7: =IFERROR(+H7-F7, "NA") -> 7.31 | K7: =IFERROR(INDEX(carbon!$A$14:$J$48,MATCH(data!$E7,carbon!$A$14:$A$48,0),2), "NA") -> 68.98 | L7: =IFERROR(INDEX(carbon!$A$14:$J$48,MATCH(data!$E7,carbon!$A$14:$A$48,0),4), "NA") -> 21.48 | M7: =IFERROR(INDEX(carbon!$A$14:$J$48,MATCH(data!$E7,carbon!$A$14:$A$48,0),6), "NA") -> 657 | N7: =IFERROR(INDEX(carbon!$A$14:$J$48,MATCH(data!$E7,carbon!$A$14:$A$48,0),8), "NA") -> 4.551
A8: Small | B8: Leaves | C8: 07 | D8: 01 | E8: Cadiz_2025_L_07_01 | F8: 3.45 | G8: 100.1 | H8: 13.72 | I8: =+G8-F8 -> 96.65 | J8: =IFERROR(+H8-F8, "NA") -> 10.27 | K8: =IFERROR(INDEX(carbon!$A$14:$J$48,MATCH(data!$E8,carbon!$A$14:$A$48,0),2), "NA") -> 73.85 | L8: =IFERROR(INDEX(carbon!$A$14:$J$48,MATCH(data!$E8,carbon!$A$14:$A$48,0),4), "NA") -> 22.28 | M8: =IFERROR(INDEX(carbon!$A$14:$J$48,MATCH(data!$E8,carbon!$A$14:$A$48,0),6), "NA") -> 334.55 | N8: =IFERROR(INDEX(carbon!$A$14:$J$48,MATCH(data!$E8,carbon!$A$14:$A$48,0),8), "NA") -> 2.835
A9: Small | B9: Leaves | C9: 08 | D9: 01 | E9: Cadiz_2025_L_08_01 | F9: 1.98 | G9: 89.68 | H9: 10.67 | I9: =+G9-F9 -> 87.7 | J9: =IFERROR(+H9-F9, "NA") -> 8.69 | K9: =IFERROR(INDEX(carbon!$A$14:$J$48,MATCH(data!$E9,carbon!$A$14:$A$48,0),2), "NA") -> 74.85 | L9: =IFERROR(INDEX(carbon!$A$14:$J$48,MATCH(data!$E9,carbon!$A$14:$A$48,0),4), "NA") -> 24.41 | M9: =IFERROR(INDEX(carbon!$A$14:$J$48,MATCH(data!$E9,carbon!$A$14:$A$48,0),6), "NA") -> 260.41 | N9: =IFERROR(INDEX(carbon!$A$14:$J$48,MATCH(data!$E9,carbon!$A$14:$A$48,0),8), "NA") -> 3.074
A10: Small | B10: Leaves | C10: 09 | D10: 01 | E10: Cadiz_2025_L_09_01 | F10: 2.01 | G10: 108.6 | H10: 11.44 | I10: =+G10-F10 -> 106.59 | J10: =IFERROR(+H10-F10, "NA") -> 9.43 | K10: =IFERROR(INDEX(carbon!$A$14:$J$48,MATCH(data!$E10,carbon!$A$14:$A$48,0),2), "NA") -> 68.45 | L10: =IFERROR(INDEX(carbon!$A$14:$J$48,MATCH(data!$E10,carbon!$A$14:$A$48,0),4), "NA") -> 23.24 | M10: =IFERROR(INDEX(carbon!$A$14:$J$48,MATCH(data!$E10,carbon!$A$14:$A$48,0),6), "NA") -> 292.9 | N10: =IFERROR(INDEX(carbon!$A$14:$J$48,MATCH(data!$E10,carbon!$A$14:$A$48,0),8), "NA") -> 2.928
A11: Small | B11: Leaves | C11: 10 | D11: 01 | E11: Cadiz_2025_L_10_01 | F11: 0.826 | G11: 10.28 | H11: 1.746 | I11: =+G11-F11 -> 9.454 | J11: =IFERROR(+H11-F11, "NA") -> 0.92 | K11: =IFERROR(INDEX(carbon!$A$14:$J$48,MATCH(data!$E11,carbon!$A$14:$A$48,0),2), "NA") -> 72.59 | L11: =IFERROR(INDEX(carbon!$A$14:$J$48,MATCH(data!$E11,carbon!$A$14:$A$48,0),4), "NA") -> 16.37 | M11: =IFERROR(INDEX(carbon!$A$14:$J$48,MATCH(data!$E11,carbon!$A$14:$A$48,0),6), "NA") -> 590.16 | N11: =IFERROR(INDEX(carbon!$A$14:$J$48,MATCH(data!$E11,carbon!$A$14:$A$48,0),8), "NA") -> 4.294
A12: Small | B12: Leaves | C12: 11 | D12: 01 | E12: Cadiz_2025_L_11_01 | F12: 0.726 | G12: 8.399 | H12: 1.448 | I12: =+G12-F12 -> 7.673 | J12: =IFERROR(+H12-F12, "NA") -> 0.722 | K12: =IFERROR(INDEX(carbon!$A$14:$J$48,MATCH(data!$E12,carbon!$A$14:$A$48,0),2), "NA") -> 75.22 | L12: =IFERROR(INDEX(carbon!$A$14:$J$48,MATCH(data!$E12,carbon!$A$14:$A$48,0),4), "NA") -> 23.63 | M12: =IFERROR(INDEX(carbon!$A$14:$J$48,MATCH(data!$E12,carbon!$A$14:$A$48,0),6), "NA") -> 349 | N12: =IFERROR(INDEX(carbon!$A$14:$J$48,MATCH(data!$E12,carbon!$A$14:$A$48,0),8), "NA") -> 3.524
A13: Small | B13: Leaves | C13: 12 | D13: 01 | E13: Cadiz_2025_L_12_01 | F13: 0.917 | G13: 11.7 | H13: 1.511 | I13: =+G13-F13 -> 10.783 | J13: =IFERROR(+H13-F13, "NA") -> 0.594 | K13: =IFERROR(INDEX(carbon!$A$14:$J$48,MATCH(data!$E13,carbon!$A$14:$A$48,0),2), "NA") -> 76.19 | L13: =IFERROR(INDEX(carbon!$A$14:$J$48,MATCH(data!$E13,carbon!$A$14:$A$48,0),4), "NA") -> 22.04 | M13: =IFERROR(INDEX(carbon!$A$14:$J$48,MATCH(data!$E13,carbon!$A$14:$A$48,0),6), "NA") -> 298.7 | N13: =IFERROR(INDEX(carbon!$A$14:$J$48,MATCH(data!$E13,carbon!$A$14:$A$48,0),8), "NA") -> 3.575
... A18: Small | B18: Leaves | C18: 17 | D18: 01 | E18: Cadiz_2025_L_17_01 | F18: 1.317 | G18: 8.154 | H18: 2.458 | I18: =+G18-F18 -> 6.837 | J18: =IFERROR(+H18-F18, "NA") -> 1.141 | K18: =IFERROR(INDEX(carbon!$A$14:$J$48,MATCH(data!$E18,carbon!$A$14:$A$48,0),2), "NA") -> 71.47 | L18: =IFERROR(INDEX(carbon!$A$14:$J$48,MATCH(data!$E18,carbon!$A$14:$A$48,0),4), "NA") -> 17.64 | M18: =IFERROR(INDEX(carbon!$A$14:$J$48,MATCH(data!$E18,carbon!$A$14:$A$48,0),6), "NA") -> 393.52 | N18: =IFERROR(INDEX(carbon!$A$14:$J$48,MATCH(data!$E18,carbon!$A$14:$A$48,0),8), "NA") -> 2.496
A19: Small | B19: Leaves | C19: 18 | D19: 01 | E19: Cadiz_2025_L_18_01 | F19: 0.531 | G19: 0 | H19: 0 | I19: 0 | J19: =IFERROR(+H19-F19, "NA") -> -0.531 | K19: =IFERROR(INDEX(carbon!$A$14:$J$48,MATCH(data!$E19,carbon!$A$14:$A$48,0),2), "NA") -> NA | L19: =IFERROR(INDEX(carbon!$A$14:$J$48,MATCH(data!$E19,carbon!$A$14:$A$48,0),4), "NA") -> NA | M19: =IFERROR(INDEX(carbon!$A$14:$J$48,MATCH(data!$E19,carbon!$A$14:$A$48,0),6), "NA") -> NA | N19: =IFERROR(INDEX(carbon!$A$14:$J$48,MATCH(data!$E19,carbon!$A$14:$A$48,0),8), "NA") -> NA
A20: Small | B20: Leaves | C20: 19 | D20: 01 | E20: Cadiz_2025_L_19_01 | F20: 0.388 | G20: 0.544 | H20: 0.439 | I20: =+G20-F20 -> 0.156 | J20: =IFERROR(+H20-F20, "NA") -> 0.051 | K20: =IFERROR(INDEX(carbon!$A$14:$J$48,MATCH(data!$E20,carbon!$A$14:$A$48,0),2), "NA") -> NA | L20: =IFERROR(INDEX(carbon!$A$14:$J$48,MATCH(data!$E20,carbon!$A$14:$A$48,0),4), "NA") -> NA | M20: =IFERROR(INDEX(carbon!$A$14:$J$48,MATCH(data!$E20,carbon!$A$14:$A$48,0),6), "NA") -> NA | N20: =IFERROR(INDEX(carbon!$A$14:$J$48,MATCH(data!$E20,carbon!$A$14:$A$48,0),8), "NA") -> NA
A21: Small | B21: Leaves | C21: 20 | D21: 01 | E21: Cadiz_2025_L_20_01 | F21: 0 | G21: 0 | H21: 0 | I21: 0 | J21: =IFERROR(+H21-F21, "NA") -> 0 | K21: =IFERROR(INDEX(carbon!$A$14:$J$48,MATCH(data!$E21,carbon!$A$14:$A$48,0),2), "NA") -> NA | L21: =IFERROR(INDEX(carbon!$A$14:$J$48,MATCH(data!$E21,carbon!$A$14:$A$48,0),4), "NA") -> NA | M21: =IFERROR(INDEX(carbon!$A$14:$J$48,MATCH(data!$E21,carbon!$A$14:$A$48,0),6), "NA") -> NA | N21: =IFERROR(INDEX(carbon!$A$14:$J$48,MATCH(data!$E21,carbon!$A$14:$A$48,0),8), "NA") -> NA
A22: Small | B22: Leaves | C22: 21 | D22: 01 | E22: Cadiz_2025_L_21_01 | F22: 0.508 | G22: 0.591 | H22: 0.53 | I22: =+G22-F22 -> 0.083 | J22: =IFERROR(+H22-F22, "NA") -> 0.022 | K22: =IFERROR(INDEX(carbon!$A$14:$J$48,MATCH(data!$E22,carbon!$A$14:$A$48,0),2), "NA") -> NA | L22: =IFERROR(INDEX(carbon!$A$14:$J$48,MATCH(data!$E22,carbon!$A$14:$A$48,0),4), "NA") -> NA | M22: =IFERROR(INDEX(carbon!$A$14:$J$48,MATCH(data!$E22,carbon!$A$14:$A$48,0),6), "NA") -> NA | N22: =IFERROR(INDEX(carbon!$A$14:$J$48,MATCH(data!$E22,carbon!$A$14:$A$48,0),8), "NA") -> NA
A23: Small | B23: Leaves | C23: 22 | D23: 01 | E23: Cadiz_2025_L_22_01 | F23: 0.475 | G23: 16.333 | H23: 1.919 | I23: =+G23-F23 -> 15.858 | J23: =IFERROR(+H23-F23, "NA") -> 1.444 | K23: =IFERROR(INDEX(carbon!$A$14:$J$48,MATCH(data!$E23,carbon!$A$14:$A$48,0),2), "NA") -> NA | L23: =IFERROR(INDEX(carbon!$A$14:$J$48,MATCH(data!$E23,carbon!$A$14:$A$48,0),4), "NA") -> NA | M23: =IFERROR(INDEX(carbon!$A$14:$J$48,MATCH(data!$E23,carbon!$A$14:$A$48,0),6), "NA") -> NA | N23: =IFERROR(INDEX(carbon!$A$14:$J$48,MATCH(data!$E23,carbon!$A$14:$A$48,0),8), "NA") -> NA
A24: Small | B24: Leaves | C24: 23 | D24: 01 | E24: Cadiz_2025_L_23_01 | F24: 0 | G24: 0 | H24: 0 | I24: 0 | J24: =IFERROR(+H24-F24, "NA") -> 0 | K24: =IFERROR(INDEX(carbon!$A$14:$J$48,MATCH(data!$E24,carbon!$A$14:$A$48,0),2), "NA") -> NA | L24: =IFERROR(INDEX(carbon!$A$14:$J$48,MATCH(data!$E24,carbon!$A$14:$A$48,0),4), "NA") -> NA | M24: =IFERROR(INDEX(carbon!$A$14:$J$48,MATCH(data!$E24,carbon!$A$14:$A$48,0),6), "NA") -> NA | N24: =IFERROR(INDEX(carbon!$A$14:$J$48,MATCH(data!$E24,carbon!$A$14:$A$48,0),8), "NA") -> NA
A25: Small | B25: Leaves | C25: 24 | D25: 01 | E25: Cadiz_2025_L_24_01 | F25: 0.469 | G25: 0.529 | H25: 0.488 | I25: =+G25-F25 -> 0.06 | J25: =IFERROR(+H25-F25, "NA") -> 0.019 | K25: =IFERROR(INDEX(carbon!$A$14:$J$48,MATCH(data!$E25,carbon!$A$14:$A$48,0),2), "NA") -> NA | L25: =IFERROR(INDEX(carbon!$A$14:$J$48,MATCH(data!$E25,carbon!$A$14:$A$48,0),4), "NA") -> NA | M25: =IFERROR(INDEX(carbon!$A$14:$J$48,MATCH(data!$E25,carbon!$A$14:$A$48,0),6), "NA") -> NA | N25: =IFERROR(INDEX(carbon!$A$14:$J$48,MATCH(data!$E25,carbon!$A$14:$A$48,0),8), "NA") -> NA
A26: Small | B26: Leaves | C26: 25 | D26: 01 | E26: Cadiz_2025_L_25_01 | F26: 0.893 | G26: 1.055 | H26: 0.932 | I26: =+G26-F26 -> 0.162 | J26: =IFERROR(+H26-F26, "NA") -> 0.039 | K26: =IFERROR(INDEX(carbon!$A$14:$J$48,MATCH(data!$E26,carbon!$A$14:$A$48,0),2), "NA") -> NA | L26: =IFERROR(INDEX(carbon!$A$14:$J$48,MATCH(data!$E26,carbon!$A$14:$A$48,0),4), "NA") -> NA | M26: =IFERROR(INDEX(carbon!$A$14:$J$48,MATCH(data!$E26,carbon!$A$14:$A$48,0),6), "NA") -> NA | N26: =IFERROR(INDEX(carbon!$A$14:$J$48,MATCH(data!$E26,carbon!$A$14:$A$48,0),8), "NA") -> NA
A27: Small | B27: Leaves | C27: 26 | D27: 01 | E27: Cadiz_2025_L_26_01 | F27: 0.659 | G27: 0.747 | H27: 0.673 | I27: =+G27-F27 -> 0.088 | J27: =IFERROR(+H27-F27, "NA") -> 0.014 | K27: =IFERROR(INDEX(carbon!$A$14:$J$48,MATCH(data!$E27,carbon!$A$14:$A$48,0),2), "NA") -> NA | L27: =IFERROR(INDEX(carbon!$A$14:$J$48,MATCH(data!$E27,carbon!$A$14:$A$48,0),4), "NA") -> NA | M27: =IFERROR(INDEX(carbon!$A$14:$J$48,MATCH(data!$E27,carbon!$A$14:$A$48,0),6), "NA") -> NA | N27: =IFERROR(INDEX(carbon!$A$14:$J$48,MATCH(data!$E27,carbon!$A$14:$A$48,0),8), "NA") -> NA
A28: Small | B28: Leaves | C28: 27 | D28: 01 | E28: Cadiz_2025_L_27_01 | F28: NA | G28: NA | H28: NA | I28: NA | J28: =IFERROR(+H28-F28, "NA") -> NA | K28: =IFERROR(+I28-G28, "NA") -> NA | L28: =IFERROR(+J28-H28, "NA") -> NA | M28: =IFERROR(+K28-I28, "NA") -> NA | N28: =IFERROR(+L28-J28, "NA") -> NA
A29: Small | B29: Leaves | C29: 28 | D29: 01 | E29: Cadiz_2025_L_28_01 | F29: NA | G29: NA | H29: NA | I29: NA | J29: =IFERROR(+H29-F29, "NA") -> NA | K29: =IFERROR(+I29-G29, "NA") -> NA | L29: =IFERROR(+J29-H29, "NA") -> NA | M29: =IFERROR(+K29-I29, "NA") -> NA | N29: =IFERROR(+L29-J29, "NA") -> NA
A30: Small | B30: Leaves | C30: 29 | D30: 01 | E30: Cadiz_2025_L_29_01 | F30: NA | G30: NA | H30: NA | I30: NA | J30: =IFERROR(+H30-F30, "NA") -> NA | K30: =IFERROR(+I30-G30, "NA") -> NA | L30: =IFERROR(+J30-H30, "NA") -> NA | M30: =IFERROR(+K30-I30, "NA") -> NA | N30: =IFERROR(+L30-J30, "NA") -> NA
A31: Small | B31: Leaves | C31: 30 | D31: 01 | E31: Cadiz_2025_L_30_01 | F31: NA | G31: NA | H31: NA | I31: NA | J31: =IFERROR(+H31-F31, "NA") -> NA | K31: =IFERROR(+I31-G31, "NA") -> NA | L31: =IFERROR(+J31-H31, "NA") -> NA | M31: =IFERROR(+K31-I31, "NA") -> NA | N31: =IFERROR(+L31-J31, "NA") -> NA
A32: Small | B32: Roots | C32: 01 | D32: 01 | E32: Cadiz_2025_R_01_01 | F32: 0.58 | G32: 15.431 | H32: 2.228 | I32: =+G32-F32 -> 14.851 | J32: =IFERROR(+H32-F32, "NA") -> 1.648 | K32: =IFERROR(INDEX(carbon!$A$14:$J$48,MATCH(data!$E32,carbon!$A$14:$A$48,0),2), "NA") -> 70.86 | L32: =IFERROR(INDEX(carbon!$A$14:$J$48,MATCH(data!$E32,carbon!$A$14:$A$48,0),4), "NA") -> 22.58 | M32: =IFERROR(INDEX(carbon!$A$14:$J$48,MATCH(data!$E32,carbon!$A$14:$A$48,0),6), "NA") -> 353.87 | N32: =IFERROR(INDEX(carbon!$A$14:$J$48,MATCH(data!$E32,carbon!$A$14:$A$48,0),8), "NA") -> 3.321
A33: Small | B33: Roots | C33: 02 | D33: 01 | E33: Cadiz_2025_R_02_01 | F33: 0.567 | G33: 23.906 | H33: 1.941 | I33: =+G33-F33 -> 23.339 | J33: =IFERROR(+H33-F33, "NA") -> 1.374 | K33: =IFERROR(INDEX(carbon!$A$14:$J$48,MATCH(data!$E33,carbon!$A$14:$A$48,0),2), "NA") -> 72.07 | L33: =IFERROR(INDEX(carbon!$A$14:$J$48,MATCH(data!$E33,carbon!$A$14:$A$48,0),4), "NA") -> 24.34 | M33: =IFERROR(INDEX(carbon!$A$14:$J$48,MATCH(data!$E33,carbon!$A$14:$A$48,0),6), "NA") -> 395 | N33: =IFERROR(INDEX(carbon!$A$14:$J$48,MATCH(data!$E33,carbon!$A$14:$A$48,0),8), "NA") -> 4.142
A34: Small | B34: Roots | C34: 03 | D34: 01 | E34: Cadiz_2025_R_03_01 | F34: 1.65 | G34: 16.172 | H34: 3.078 | I34: =+G34-F34 -> 14.522 | J34: =IFERROR(+H34-F34, "NA") -> 1.428 | K34: =IFERROR(INDEX(carbon!$A$14:$J$48,MATCH(data!$E34,carbon!$A$14:$A$48,0),2), "NA") -> 70.98 | L34: =IFERROR(INDEX(carbon!$A$14:$J$48,MATCH(data!$E34,carbon!$A$14:$A$48,0),4), "NA") -> 20.7 | M34: =IFERROR(INDEX(carbon!$A$14:$J$48,MATCH(data!$E34,carbon!$A$14:$A$48,0),6), "NA") -> 366.05 | N34: =IFERROR(INDEX(carbon!$A$14:$J$48,MATCH(data!$E34,carbon!$A$14:$A$48,0),8), "NA") -> 3.098
A35: Small | B35: Roots | C35: 04 | D35: 01 | E35: Cadiz_2025_R_04_01 | F35: 0.525 | G35: 27.42 | H35: 2.561 | I35: =+G35-F35 -> 26.895 | J35: =IFERROR(+H35-F35, "NA") -> 2.036 | K35: =IFERROR(INDEX(carbon!$A$14:$J$48,MATCH(data!$E35,carbon!$A$14:$A$48,0),2), "NA") -> 78.81 | L35: =IFERROR(INDEX(carbon!$A$14:$J$48,MATCH(data!$E35,carbon!$A$14:$A$48,0),4), "NA") -> 28.05 | M35: =IFERROR(INDEX(carbon!$A$14:$J$48,MATCH(data!$E35,carbon!$A$14:$A$48,0),6), "NA") -> 363.62 | N35: =IFERROR(INDEX(carbon!$A$14:$J$48,MATCH(data!$E35,carbon!$A$14:$A$48,0),8), "NA") -> 2.178
A36: Small | B36: Roots | C36: 05 | D36: 01 | E36: Cadiz_2025_R_05_01 | F36: 0.496 | G36: 9.45 | H36: 1.685 | I36: =+G36-F36 -> 8.954 | J36: =IFERROR(+H36-F36, "NA") -> 1.189 | K36: =IFERROR(INDEX(carbon!$A$14:$J$48,MATCH(data!$E36,carbon!$A$14:$A$48,0),2), "NA") -> 70.71 | L36: =IFERROR(INDEX(carbon!$A$14:$J$48,MATCH(data!$E36,carbon!$A$14:$A$48,0),4), "NA") -> 17.4 | M36: =IFERROR(INDEX(carbon!$A$14:$J$48,MATCH(data!$E36,carbon!$A$14:$A$48,0),6), "NA") -> 341.9 | N36: =IFERROR(INDEX(carbon!$A$14:$J$48,MATCH(data!$E36,carbon!$A$14:$A$48,0),8), "NA") -> 4.41
A37: Small | B37: Roots | C37: 06 | D37: 01 | E37: Cadiz_2025_R_06_01 | F37: 1.032 | G37: 18.178 | H37: 2.848 | I37: =+G37-F37 -> 17.146 | J37: =IFERROR(+H37-F37, "NA") -> 1.816 | K37: =IFERROR(INDEX(carbon!$A$14:$J$48,MATCH(data!$E37,carbon!$A$14:$A$48,0),2), "NA") -> 73.91 | L37: =IFERROR(INDEX(carbon!$A$14:$J$48,MATCH(data!$E37,carbon!$A$14:$A$48,0),4), "NA") -> 24.79 | M37: =IFERROR(INDEX(carbon!$A$14:$J$48,MATCH(data!$E37,carbon!$A$14:$A$48,0),6), "NA") -> 365.95 | N37: =IFERROR(INDEX(carbon!$A$14:$J$48,MATCH(data!$E37,carbon!$A$14:$A$48,0),8), "NA") -> 3.41
A38: Small | B38: Roots | C38: 07 | D38: 01 | E38: Cadiz_2025_R_07_01 | F38: 0.935 | G38: 28.66 | H38: 3.697 | I38: =+G38-F38 -> 27.725 | J38: =IFERROR(+H38-F38, "NA") -> 2.762 | K38: =IFERROR(INDEX(carbon!$A$14:$J$48,MATCH(data!$E38,carbon!$A$14:$A$48,0),2), "NA") -> 74.57 | L38: =IFERROR(INDEX(carbon!$A$14:$J$48,MATCH(data!$E38,carbon!$A$14:$A$48,0),4), "NA") -> 23.16 | M38: =IFERROR(INDEX(carbon!$A$14:$J$48,MATCH(data!$E38,carbon!$A$14:$A$48,0),6), "NA") -> 302.08 | N38: =IFERROR(INDEX(carbon!$A$14:$J$48,MATCH(data!$E38,carbon!$A$14:$A$48,0),8), "NA") -> 2.848
A39: Small | B39: Roots | C39: 08 | D39: 01 | E39: Cadiz_2025_R_08_01 | F39: 1.293 | G39: 15.39 | H39: 2.77 | I39: =+G39-F39 -> 14.097 | J39: =IFERROR(+H39-F39, "NA") -> 1.477 | K39: =IFERROR(INDEX(carbon!$A$14:$J$48,MATCH(data!$E39,carbon!$A$14:$A$48,0),2), "NA") -> 78.72 | L39: =IFERROR(INDEX(carbon!$A$14:$J$48,MATCH(data!$E39,carbon!$A$14:$A$48,0),4), "NA") -> 25.66 | M39: =IFERROR(INDEX(carbon!$A$14:$J$48,MATCH(data!$E39,carbon!$A$14:$A$48,0),6), "NA") -> 463.97 | N39: =IFERROR(INDEX(carbon!$A$14:$J$48,MATCH(data!$E39,carbon!$A$14:$A$48,0),8), "NA") -> 4.404
A40: Small | B40: Roots | C40: 09 | D40: 01 | E40: Cadiz_2025_R_09_01 | F40: 0.511 | G40: 35.79 | H40: 3.625 | I40: =+G40-F40 -> 35.279 | J40: =IFERROR(+H40-F40, "NA") -> 3.114 | K40: =IFERROR(INDEX(carbon!$A$14:$J$48,MATCH(data!$E40,carbon!$A$14:$A$48,0),2), "NA") -> 72.12 | L40: =IFERROR(INDEX(carbon!$A$14:$J$48,MATCH(data!$E40,carbon!$A$14:$A$48,0),4), "NA") -> 24.95 | M40: =IFERROR(INDEX(carbon!$A$14:$J$48,MATCH(data!$E40,carbon!$A$14:$A$48,0),6), "NA") -> 725.53 | N40: =IFERROR(INDEX(carbon!$A$14:$J$48,MATCH(data!$E40,carbon!$A$14:$A$48,0),8), "NA") -> 5.969
A41: Small | B41: Roots | C41: 10 | D41: 01 | E41: Cadiz_2025_R_10_01 | F41: 0.813 | G41: 10.93 | H41: 2.101 | I41: =+G41-F41 -> 10.117 | J41: =IFERROR(+H41-F41, "NA") -> 1.288 | K41: =IFERROR(INDEX(carbon!$A$14:$J$48,MATCH(data!$E41,carbon!$A$14:$A$48,0),2), "NA") -> NA | L41: =IFERROR(INDEX(carbon!$A$14:$J$48,MATCH(data!$E41,carbon!$A$14:$A$48,0),4), "NA") -> NA | M41: =IFERROR(INDEX(carbon!$A$14:$J$48,MATCH(data!$E41,carbon!$A$14:$A$48,0),6), "NA") -> NA | N41: =IFERROR(INDEX(carbon!$A$14:$J$48,MATCH(data!$E41,carbon!$A$14:$A$48,0),8), "NA") -> NA
A42: Small | B42: Roots | C42: 11 | D42: 01 | E42: Cadiz_2025_R_11_01 | F42: 0.656 | G42: 8.865 | H42: 1.428 | I42: =+G42-F42 -> 8.209 | J42: =IFERROR(+H42-F42, "NA") -> 0.772 | K42: =IFERROR(INDEX(carbon!$A$14:$J$48,MATCH(data!$E42,carbon!$A$14:$A$48,0),2), "NA") -> NA | L42: =IFERROR(INDEX(carbon!$A$14:$J$48,MATCH(data!$E42,carbon!$A$14:$A$48,0),4), "NA") -> NA | M42: =IFERROR(INDEX(carbon!$A$14:$J$48,MATCH(data!$E42,carbon!$A$14:$A$48,0),6), "NA") -> NA | N42: =IFERROR(INDEX(carbon!$A$14:$J$48,MATCH(data!$E42,carbon!$A$14:$A$48,0),8), "NA") -> NA
A43: Small | B43: Roots | C43: 12 | D43: 01 | E43: Cadiz_2025_R_12_01 | F43: 0.544 | G43: 13.91 | H43: 2.092 | I43: =+G43-F43 -> 13.366 | J43: =IFERROR(+H43-F43, "NA") -> 1.548 | K43: =IFERROR(INDEX(carbon!$A$14:$J$48,MATCH(data!$E43,carbon!$A$14:$A$48,0),2), "NA") -> 78.71 | L43: =IFERROR(INDEX(carbon!$A$14:$J$48,MATCH(data!$E43,carbon!$A$14:$A$48,0),4), "NA") -> 13.23 | M43: =IFERROR(INDEX(carbon!$A$14:$J$48,MATCH(data!$E43,carbon!$A$14:$A$48,0),6), "NA") -> 344.57 | N43: =IFERROR(INDEX(carbon!$A$14:$J$48,MATCH(data!$E43,carbon!$A$14:$A$48,0),8), "NA") -> 2.682
... A48: Small | B48: Roots | C48: 17 | D48: 01 | E48: Cadiz_2025_R_17_01 | F48: 1.269 | G48: 14.197 | H48: 3.037 | I48: =+G48-F48 -> 12.928 | J48: =IFERROR(+H48-F48, "NA") -> 1.768 | K48: =IFERROR(INDEX(carbon!$A$14:$J$48,MATCH(data!$E48,carbon!$A$14:$A$48,0),2), "NA") -> 75.5 | L48: =IFERROR(INDEX(carbon!$A$14:$J$48,MATCH(data!$E48,carbon!$A$14:$A$48,0),4), "NA") -> 15.92 | M48: =IFERROR(INDEX(carbon!$A$14:$J$48,MATCH(data!$E48,carbon!$A$14:$A$48,0),6), "NA") -> 475.63 | N48: =IFERROR(INDEX(carbon!$A$14:$J$48,MATCH(data!$E48,carbon!$A$14:$A$48,0),8), "NA") -> 2.602
...

Sheet carbon
D1: PLQ_LEE_LCE
D2: Formulaire de résultats
D3: DETERMINATION DU CARBONE TOTAL, ORGANIQUE ET INORGANIQUE DANS LES SOLS
A5: Opérateur :
A6: Date d'analyse :
A7: RE :
A8: Norme :
B10: Analyse du Carbone total | F10: Analyse du Carbone inorganique
A11: N° éch | B11: Prise d'essai humide (mg) | C11: Matière sèche (%) | D11: Masse C mesurée (mg) | E11: Concentration Ctot (g de C/kg de matière sèche) | F11: Prise d'essai humide (mg) | G11: Matière sèche (%) | H11: Concentration IC mesurée (mg) | I11: Concentration IC (g de C/kg de matière sèche) | J11: Concentration COT (g de C/kg de matière sèche)
E13: - | I13: - | J13: -
A14: Cadiz_2025_L_01 | B14: 97.99 | C14: 1 | D14: 31.56 | E14: =(D14*1000/B14)*C14 -> 322.07368 | F14: 315.6 | G14: 1 | H14: 3.608 | I14: =(H14*1000/F14)*G14 -> 11.432193 | J14: =E14-I14 -> 310.64149
A15: Cadiz_2025_L_02 | B15: 70.47 | C15: 1 | D15: 22.05 | E15: =(D15*1000/B15)*C15 -> 312.89911 | F15: 351.92 | G15: 1 | H15: 3.563 | I15: =(H15*1000/F15)*G15 -> 10.12446 | J15: =E15-I15 -> 302.77465
A16: Cadiz_2025_L_03 | B16: 79.33 | C16: 1 | D16: 23.98 | E16: =(D16*1000/B16)*C16 -> 302.28161 | F16: 320.35 | G16: 1 | H16: 2.636 | I16: =(H16*1000/F16)*G16 -> 8.2285001 | J16: =E16-I16 -> 294.05311
A17: Cadiz_2025_L_04 | B17: 73.99 | C17: 1 | D17: 24.5 | E17: =(D17*1000/B17)*C17 -> 331.12583 | F17: 281.98 | G17: 1 | H17: 3.183 | I17: =(H17*1000/F17)*G17 -> 11.288035 | J17: =E17-I17 -> 319.83779
A18: Cadiz_2025_L_05 | B18: 74.01 | C18: 1 | D18: 18.35 | E18: =(D18*1000/B18)*C18 -> 247.93947 | F18: 727.36 | G18: 1 | H18: 6.267 | I18: =(H18*1000/F18)*G18 -> 8.6160911 | J18: =E18-I18 -> 239.32338
A19: Cadiz_2025_L_06 | B19: 68.98 | C19: 1 | D19: 21.48 | E19: =(D19*1000/B19)*C19 -> 311.39461 | F19: 657 | G19: 1 | H19: 4.551 | I19: =(H19*1000/F19)*G19 -> 6.9269406 | J19: =E19-I19 -> 304.46767
A20: Cadiz_2025_L_07 | B20: 73.85 | C20: 1 | D20: 22.28 | E20: =(D20*1000/B20)*C20 -> 301.69262 | F20: 334.55 | G20: 1 | H20: 2.835 | I20: =(H20*1000/F20)*G20 -> 8.4740696 | J20: =E20-I20 -> 293.21855
A21: Cadiz_2025_L_08 | B21: 74.85 | C21: 1 | D21: 24.41 | E21: =(D21*1000/B21)*C21 -> 326.1189 | F21: 260.41 | G21: 1 | H21: 3.074 | I21: =(H21*1000/F21)*G21 -> 11.804462 | J21: =E21-I21 -> 314.31444
A22: Cadiz_2025_L_09 | B22: 68.45 | C22: 1 | D22: 23.24 | E22: =(D22*1000/B22)*C22 -> 339.5179 | F22: 292.9 | G22: 1 | H22: 2.928 | I22: =(H22*1000/F22)*G22 -> 9.9965859 | J22: =E22-I22 -> 329.52131
A23: Cadiz_2025_L_10 | B23: 72.59 | C23: 1 | D23: 16.37 | E23: =(D23*1000/B23)*C23 -> 225.51316 | F23: 590.16 | G23: 1 | H23: 4.294 | I23: =(H23*1000/F23)*G23 -> 7.275993 | J23: =E23-I23 -> 218.23716
A24: Cadiz_2025_L_11 | B24: 75.22 | C24: 1 | D24: 23.63 | E24: =(D24*1000/B24)*C24 -> 314.14517 | F24: 349 | G24: 1 | H24: 3.524 | I24: =(H24*1000/F24)*G24 -> 10.097421 | J24: =E24-I24 -> 304.04775
A25: Cadiz_2025_L_12 | B25: 76.19 | C25: 1 | D25: 22.04 | E25: =(D25*1000/B25)*C25 -> 289.27681 | F25: 298.7 | G25: 1 | H25: 3.575 | I25: =(H25*1000/F25)*G25 -> 11.96853 | J25: =E25-I25 -> 277.30828
... A48: Cadiz_2025_R_17 | B48: 75.5 | C48: 1 | D48: 15.92 | E48: =(D48*1000/B48)*C48 -> 210.86093 | F48: 475.63 | G48: 1 | H48: 2.602 | I48: =(H48*1000/F48)*G48 -> 5.4706389 | J48: =E48-I48 -> 205.39029
A51: * Samples not well homogenised
