Workbook

Sheet data
A1: type | B1: name | C1: site | D1: longitude | E1: latitude | F1: poskey.benthos | G1: poskey.sediment | H1: picture | I1: habitat | J1: seagrassA | K1: seagrassB | L1: sorting lab | M1: seagrass.cover.Laurant | N1: spectral camera | O1: remark
A2: grid | B2: RG 25 | C2: rewilded | D2: -8.6904504 | E2: 40.672106 | F2: 2025001 | G2: 2025048 | H2: P7150059 | I2: algae | J2: =VLOOKUP($F2,'seagrass biomass'!$G:$L,2,FALSE) -> 0 | K2: =VLOOKUP($F2,'seagrass biomass'!$G:$L,3,FALSE) -> 0 | L2: aveiro
A3: random | B3: RR 47 | C3: rewilded | D3: -8.6905032 | E3: 40.67236 | F3: 2025002 | G3: 2025043 | H3: P7150061 | I3: seagrass | J3: =VLOOKUP($F3,'seagrass biomass'!$G:$L,2,FALSE) -> 0 | K3: =VLOOKUP($F3,'seagrass biomass'!$G:$L,3,FALSE) -> 0 | L3: aveiro
A4: grid | B4: RG 17 | C4: rewilded | D4: -8.6909023 | E4: 40.672397 | F4: 2025003 | G4: 2025047 | H4: P7150062 | I4: seagrass | J4: =VLOOKUP($F4,'seagrass biomass'!$G:$L,2,FALSE) -> 315 | K4: =VLOOKUP($F4,'seagrass biomass'!$G:$L,3,FALSE) -> 250 | L4: aveiro | M4: no | N4: no
A5: grid | B5: RG 9 | C5: rewilded | D5: -8.6913541 | E5: 40.672687 | F5: 2025004 | G5: 2025041 | H5: P7150063 | I5: seagrass | J5: =VLOOKUP($F5,'seagrass biomass'!$G:$L,2,FALSE) -> 42 | K5: =VLOOKUP($F5,'seagrass biomass'!$G:$L,3,FALSE) -> 141 | L5: aveiro
A6: grid | B6: RG 1 | C6: rewilded | D6: -8.691806 | E6: 40.672978 | F6: 2025005 | G6: 2025050 | H6: P7150065 | I6: seagrass | J6: =VLOOKUP($F6,'seagrass biomass'!$G:$L,2,FALSE) -> 2222 | K6: =VLOOKUP($F6,'seagrass biomass'!$G:$L,3,FALSE) -> 939 | L6: aveiro
A7: grid | B7: RG 2 | C7: rewilded | D7: -8.6914241 | E7: 40.673322 | F7: 2025006 | G7: 2025059 | H7: P7150066 | I7: bare | J7: =VLOOKUP($F7,'seagrass biomass'!$G:$L,2,FALSE) -> 17 | K7: =VLOOKUP($F7,'seagrass biomass'!$G:$L,3,FALSE) -> 0 | L7: aveiro
A8: grid | B8: RG 10 | C8: rewilded | D8: -8.6909723 | E8: 40.673031 | F8: 2025007 | G8: 2025056 | H8: P7150067 | I8: algae | J8: =VLOOKUP($F8,'seagrass biomass'!$G:$L,2,FALSE) -> 0 | K8: =VLOOKUP($F8,'seagrass biomass'!$G:$L,3,FALSE) -> 0 | L8: aveiro
A9: random | B9: RR 41 | C9: rewilded | D9: -8.6906446 | E9: 40.672994 | F9: 2025008 | G9: 2025060 | H9: P7150068 | I9: seagrass | J9: =VLOOKUP($F9,'seagrass biomass'!$G:$L,2,FALSE) -> 2418 | K9: =VLOOKUP($F9,'seagrass biomass'!$G:$L,3,FALSE) -> 1706 | L9: aveiro
A10: random | B10: RR 40 | C10: rewilded | D10: -8.6908498 | E10: 40.672778 | F10: 2025009 | G10: 2025045 | H10: P7150069 | I10: seagrass | J10: =VLOOKUP($F10,'seagrass biomass'!$G:$L,2,FALSE) -> 1377 | K10: =VLOOKUP($F10,'seagrass biomass'!$G:$L,3,FALSE) -> 1864 | L10: aveiro
A11: grid | B11: RG 18 | C11: rewilded | D11: -8.6905204 | E11: 40.672741 | F11: 2025010 | G11: 2025049 | H11: P7150070 | I11: seagrass | J11: =VLOOKUP($F11,'seagrass biomass'!$G:$L,2,FALSE) -> 2797 | K11: =VLOOKUP($F11,'seagrass biomass'!$G:$L,3,FALSE) -> 1048 | L11: aveiro
A12: random | B12: RR 48 | C12: rewilded | D12: -8.6902337 | E12: 40.672737 | F12: 2025011 | G12: 2025042 | H12: P7150071 | I12: seagrass | J12: =VLOOKUP($F12,'seagrass biomass'!$G:$L,2,FALSE) -> 3628 | K12: =VLOOKUP($F12,'seagrass biomass'!$G:$L,3,FALSE) -> 977 | L12: aveiro
A13: random | B13: RR 49 | C13: rewilded | D13: -8.6897936 | E13: 40.67296 | F13: 2025012 | G13: 2025054 | H13: P7150072 | I13: bare | J13: =VLOOKUP($F13,'seagrass biomass'!$G:$L,2,FALSE) -> 0 | K13: =VLOOKUP($F13,'seagrass biomass'!$G:$L,3,FALSE) -> 0 | L13: aveiro
A14: grid | B14: RG 19 | C14: rewilded | D14: -8.6901386 | E14: 40.673085 | F14: 2025013 | G14: 2025046 | H14: P7150073 | I14: seagrass | J14: =VLOOKUP($F14,'seagrass biomass'!$G:$L,2,FALSE) -> 1701 | K14: =VLOOKUP($F14,'seagrass biomass'!$G:$L,3,FALSE) -> 1821 | L14: aveiro
A15: grid | B15: RG 11 | C15: rewilded | D15: -8.6905904 | E15: 40.673375 | F15: 2025014 | G15: 2025051 | H15: P7150074 | I15: algae | J15: =VLOOKUP($F15,'seagrass biomass'!$G:$L,2,FALSE) -> 0 | K15: =VLOOKUP($F15,'seagrass biomass'!$G:$L,3,FALSE) -> 0 | L15: aveiro
A16: random | B16: RR 34 | C16: rewilded | D16: -8.6906575 | E16: 40.67332 | F16: 2025015 | G16: 2025053 | H16: P7150075 | I16: algae | J16: =VLOOKUP($F16,'seagrass biomass'!$G:$L,2,FALSE) -> 31 | K16: =VLOOKUP($F16,'seagrass biomass'!$G:$L,3,FALSE) -> 189 | L16: aveiro
A17: grid | B17: RG 3 | C17: rewilded | D17: -8.6910423 | E17: 40.673666 | F17: 2025016 | G17: 2025044 | H17: P7150076 | I17: seagrass | J17: =VLOOKUP($F17,'seagrass biomass'!$G:$L,2,FALSE) -> 871 | K17: =VLOOKUP($F17,'seagrass biomass'!$G:$L,3,FALSE) -> 401 | L17: aveiro | O17: edge bare and seagrass
A18: grid | B18: RG 4 | C18: rewilded | D18: -8.6906604 | E18: 40.67401 | F18: 2025017 | G18: 2025055 | H18: P7150077 | I18: seagrass | J18: =VLOOKUP($F18,'seagrass biomass'!$G:$L,2,FALSE) -> 994 | K18: =VLOOKUP($F18,'seagrass biomass'!$G:$L,3,FALSE) -> 343 | L18: aveiro
A19: random | B19: RR 35 | C19: rewilded | D19: -8.6905265 | E19: 40.673644 | F19: 2025018 | G19: 20250? | H19: P7150078 | I19: seagrass | J19: =VLOOKUP($F19,'seagrass biomass'!$G:$L,2,FALSE) -> 2523 | K19: =VLOOKUP($F19,'seagrass biomass'!$G:$L,3,FALSE) -> 1219 | L19: aveiro
A20: grid | B20: RG 12 | C20: rewilded | D20: -8.6902085 | E20: 40.673719 | F20: 2025019 | G20: 2025052 | H20: Laurant | I20: seagrass | J20: =VLOOKUP($F20,'seagrass biomass'!$G:$L,2,FALSE) -> 2695 | K20: =VLOOKUP($F20,'seagrass biomass'!$G:$L,3,FALSE) -> 1160 | L20: aveiro | M20: 96 | N20: AVE0-AVE20 | O20: info spectral cam notes Laurant
A21: grid | B21: RG 21 | C21: rewilded | D21: -8.6893748 | E21: 40.673773 | F21: 2025020 | G21: 2025061 | H21: P7150079 | I21: bare | J21: =VLOOKUP($F21,'seagrass biomass'!$G:$L,2,FALSE) -> 0 | K21: =VLOOKUP($F21,'seagrass biomass'!$G:$L,3,FALSE) -> 0 | L21: aveiro
A22: random | B22: RR 43 | C22: rewilded | D22: -8.6895451 | E22: 40.673856 | F22: 2025021 | G22: 2025057 | H22: P7150080 | I22: seagrass | J22: =VLOOKUP($F22,'seagrass biomass'!$G:$L,2,FALSE) -> 933 | K22: =VLOOKUP($F22,'seagrass biomass'!$G:$L,3,FALSE) -> 750 | L22: aveiro
A23: random | B23: RR 44 | C23: rewilded | D23: -8.6896032 | E23: 40.674076 | F23: 2025022 | G23: 2025072 | H23: P7150081 | I23: algae | J23: =VLOOKUP($F23,'seagrass biomass'!$G:$L,2,FALSE) -> 85 | K23: =VLOOKUP($F23,'seagrass biomass'!$G:$L,3,FALSE) -> 719 | L23: aveiro
A24: grid | B24: RG 13 | C24: rewilded | D24: -8.6898267 | E24: 40.674063 | F24: 2025023 | G24: 2025075 | H24: P7150082 | I24: seagrass | J24: =VLOOKUP($F24,'seagrass biomass'!$G:$L,2,FALSE) -> 2790 | K24: =VLOOKUP($F24,'seagrass biomass'!$G:$L,3,FALSE) -> 888 | L24: aveiro | M24: 100 | N24: A1-A20
A25: random | B25: RR 36 | C25: rewilded | D25: -8.6902026 | E25: 40.674295 | F25: 2025024 | G25: 2025080 | H25: P7150083 | I25: seagrass | J25: =VLOOKUP($F25,'seagrass biomass'!$G:$L,2,FALSE) -> 2113 | K25: =VLOOKUP($F25,'seagrass biomass'!$G:$L,3,FALSE) -> 675 | L25: aveiro | M25: 100 | N25: AVE21-AVE40
A26: grid | B26: RG 5 | C26: rewilded | D26: -8.6902785 | E26: 40.674354 | F26: 2025025 | G26: 2025052? | H26: P7150084 | I26: seagrass | J26: =VLOOKUP($F26,'seagrass biomass'!$G:$L,2,FALSE) -> 2171 | K26: =VLOOKUP($F26,'seagrass biomass'!$G:$L,3,FALSE) -> 933 | L26: aveiro | M26: 100 | N26: AVE41-AVE60
A27: grid | B27: RG 6 | C27: rewilded | D27: -8.6898967 | E27: 40.674698 | F27: 2025026 | G27: 2025070 | H27: P7150085 | I27: bare | J27: =VLOOKUP($F27,'seagrass biomass'!$G:$L,2,FALSE) -> 0 | K27: =VLOOKUP($F27,'seagrass biomass'!$G:$L,3,FALSE) -> 0 | L27: aveiro | M27: 0 | N27: A21-A40
A28: random | B28: RR 37 | C28: rewilded | D28: -8.6895364 | E28: 40.674448 | F28: 2025027 | G28: 2025073 | H28: P7150086 | I28: algae | J28: =VLOOKUP($F28,'seagrass biomass'!$G:$L,2,FALSE) -> 39 | K28: =VLOOKUP($F28,'seagrass biomass'!$G:$L,3,FALSE) -> 161 | L28: aveiro
A29: grid | B29: RG 14 | C29: rewilded | D29: -8.6894448 | E29: 40.674407 | F29: 2025028 | G29: 2025063 | H29: P7150087 | I29: seagrass | J29: =VLOOKUP($F29,'seagrass biomass'!$G:$L,2,FALSE) -> 2715 | K29: =VLOOKUP($F29,'seagrass biomass'!$G:$L,3,FALSE) -> 1696 | L29: aveiro
A30: random | B30: RR 45 | C30: rewilded | D30: -8.6891629 | E30: 40.674483 | F30: 2025029 | G30: 2025079 | H30: P7150088 | I30: seagrass | J30: =VLOOKUP($F30,'seagrass biomass'!$G:$L,2,FALSE) -> 1294 | K30: =VLOOKUP($F30,'seagrass biomass'!$G:$L,3,FALSE) -> 454 | L30: aveiro | M30: 25 | N30: A161-A180
A31: grid | B31: RG 22 | C31: rewilded | D31: -8.6889929 | E31: 40.674117 | F31: 2025030 | G31: 2025078 | H31: P7150089 | I31: bare | J31: =VLOOKUP($F31,'seagrass biomass'!$G:$L,2,FALSE) -> 228 | K31: =VLOOKUP($F31,'seagrass biomass'!$G:$L,3,FALSE) -> 191 | L31: aveiro | M31: 50 | N31: A181-A200
A32: random | B32: RR 51 | C32: rewilded | D32: -8.6890769 | E32: 40.673988 | F32: 2025031 | G32: 2025074 | H32: P7150090 | I32: bare | J32: =VLOOKUP($F32,'seagrass biomass'!$G:$L,2,FALSE) -> 0 | K32: =VLOOKUP($F32,'seagrass biomass'!$G:$L,3,FALSE) -> 0 | L32: aveiro
A33: random | B33: RR 52 | C33: rewilded | D33: -8.6882517 | E33: 40.674107 | F33: 2025032 | G33: 2025066 | H33: P7150091 | I33: bare | J33: =VLOOKUP($F33,'seagrass biomass'!$G:$L,2,FALSE) -> 0 | K33: =VLOOKUP($F33,'seagrass biomass'!$G:$L,3,FALSE) -> 0 | L33: aveiro
A34: grid | B34: RG 31 | C34: rewilded | D34: -8.6881592 | E34: 40.67417 | F34: 2025033 | G34: 2025071 | H34: P7160092 | I34: bare | J34: =VLOOKUP($F34,'seagrass biomass'!$G:$L,2,FALSE) -> 0 | K34: =VLOOKUP($F34,'seagrass biomass'!$G:$L,3,FALSE) -> 0 | L34: aveiro
A35: grid | B35: RG 23 | C35: rewilded | D35: -8.6886111 | E35: 40.674461 | F35: 2025034 | G35: 2025110 | H35: P7160093 | I35: bare | J35: =VLOOKUP($F35,'seagrass biomass'!$G:$L,2,FALSE) -> 0 | K35: =VLOOKUP($F35,'seagrass biomass'!$G:$L,3,FALSE) -> 0 | L35: aveiro | M35: 0 | N35: A141-A160
A36: random | B36: RR 46 | C36: rewilded | D36: -8.6887206 | E36: 40.674762 | F36: 2025035 | G36: 2025100 | H36: P7160094 | I36: seagrass | J36: =VLOOKUP($F36,'seagrass biomass'!$G:$L,2,FALSE) -> 206.02 | K36: =VLOOKUP($F36,'seagrass biomass'!$G:$L,3,FALSE) -> 212.4 | L36: aveiro | M36: 40 | N36: A101-A120
A37: grid | B37: RG 16 | C37: rewilded | D37: -8.688681 | E37: 40.675095 | F37: 2025036 | G37: 2025096 | H37: P7160095 | I37: seagrass | J37: =VLOOKUP($F37,'seagrass biomass'!$G:$L,2,FALSE) -> 645 | K37: =VLOOKUP($F37,'seagrass biomass'!$G:$L,3,FALSE) -> 607 | L37: aveiro | M37: 50 | N37: A121-A140
A38: grid | B38: RG 15 | C38: rewilded | D38: -8.6890629 | E38: 40.674751 | F38: 2025037 | G38: 2025095 | H38: P7160096 | I38: seagrass | J38: =VLOOKUP($F38,'seagrass biomass'!$G:$L,2,FALSE) -> 1871 | K38: =VLOOKUP($F38,'seagrass biomass'!$G:$L,3,FALSE) -> 1585 | L38: aveiro
A39: random | B39: RR 38 | C39: rewilded | D39: -8.6893755 | E39: 40.674802 | F39: 2025038 | G39: 2025062 | H39: P7160102 | I39: seagrass | J39: =VLOOKUP($F39,'seagrass biomass'!$G:$L,2,FALSE) -> 1642 | K39: =VLOOKUP($F39,'seagrass biomass'!$G:$L,3,FALSE) -> 1381 | L39: aveiro
A40: grid | B40: RG 7 | C40: rewilded | D40: -8.6895148 | E40: 40.675042 | F40: 2025039 | G40: 20250? | H40: P7160103 | I40: bare | J40: =VLOOKUP($F40,'seagrass biomass'!$G:$L,2,FALSE) -> 0 | K40: =VLOOKUP($F40,'seagrass biomass'!$G:$L,3,FALSE) -> 0 | L40: aveiro | M40: 0 | N40: A41-A60
...

Sheet seagrass biomass
A1: teller | B1: Code | C1: poskey | D1: AB | E1: dry weight (mg) | F1: remark | G1: Average of dry weight (mg) | H1: Column Labels | O1: Aveiro 07/2025
A2: 1 | B2: 10A | C2: 2025010 | D2: A | E2: 2797 | G2: Row Labels | H2: A | I2: B | J2: (blank) | K2: Grand Total | O2: Oven 48h at 60°C | R2: A = Above ground biomass
A3: 2 | B3: 10B | C3: 2025010 | D3: B | E3: 1048 | G3: 2025003 | H3: 315 | I3: 250 | K3: 282.5 | R3: B= Belowground biomass
A4: 3 | B4: 113AN | C4: 2025113 | D4: A | E4: 1876 | G4: 2025004 | H4: 42 | I4: 141 | K4: 91.5 | O4: Code | P4: dry weight (mg)
A5: 4 | B5: 113BN | C5: 2025113 | D5: B | E5: 608 | G5: 2025005 | H5: 2222 | I5: 939 | K5: 1580.5 | O5: 10A | P5: 2797 | R5: Seagrass leaves and Roots/Rhizomes
A6: 5 | B6: 115AN | C6: 2025115 | D6: A | E6: =3982-6.2 -> 3975.8 | G6: 2025006 | H6: 17 | I6: 0 | K6: 8.5 | O6: 10B | P6: 1048
A7: 6 | B7: 115BN | C7: 2025115 | D7: B | E7: 2080 | G7: 2025007 | H7: 0 | I7: 0 | K7: 0 | O7: 113AN | P7: 1876
A8: 7 | B8: 116AN | C8: 2025116 | D8: A | E8: 3531 | G8: 2025008 | H8: 2418 | I8: 1706 | K8: 2062 | O8: 113BN | P8: 608
A9: 8 | B9: 116BN | C9: 2025116 | D9: B | E9: 2364 | G9: 2025009 | H9: 1377 | I9: 1864 | K9: 1620.5 | O9: 115AN | P9: =3982-6.2 -> 3975.8
A10: 9 | B10: 117AN | C10: 2025117 | D10: A | E10: 750 | G10: 2025010 | H10: 2797 | I10: 1048 | K10: 1922.5 | O10: 115BN | P10: 2080
A11: 10 | B11: 117BN | C11: 2025117 | D11: B | E11: 345 | G11: 2025011 | H11: 3628 | I11: 977 | K11: 2302.5 | O11: 116AN | P11: 3531
A12: 11 | B12: 119A | C12: 2025119 | D12: A | E12: 754 | G12: 2025012 | H12: 0 | I12: 0 | K12: 0 | O12: 116BN | P12: 2364
A13: 12 | B13: 119B | C13: 2025119 | D13: B | E13: 582 | G13: 2025013 | H13: 1701 | I13: 1821 | K13: 1761 | O13: 117AN | P13: 750
A14: 13 | B14: 11A | C14: 2025011 | D14: A | E14: 3628 | G14: 2025014 | H14: 0 | I14: 0 | K14: 0 | O14: 117BN | P14: 345
A15: 14 | B15: 11B | C15: 2025011 | D15: B | E15: 977 | G15: 2025015 | H15: 31 | I15: 189 | K15: 110 | O15: 119A | P15: 754
A16: 15 | B16: 120AN | C16: 2025120 | D16: A | E16: 12 | G16: 2025016 | H16: 871 | I16: 401 | K16: 636 | O16: 119B | P16: 582
A17: 16 | B17: 120BN | C17: 2025120 | D17: B | E17: 118 | G17: 2025017 | H17: 994 | I17: 343 | K17: 668.5 | O17: 11A | P17: 3628
A18: 17 | B18: 121AN | C18: 2025121 | D18: A | E18: 0 | G18: 2025018 | H18: 2523 | I18: 1219 | K18: 1871 | O18: 11B | P18: 977
A19: 18 | B19: 121BN | C19: 2025121 | D19: B | E19: 0 | G19: 2025019 | H19: 2695 | I19: 1160 | K19: 1927.5 | O19: 120AN | P19: 12
A20: 19 | B20: 122AN | C20: 2025122 | D20: A | E20: 2650 | G20: 2025021 | H20: 933 | I20: 750 | K20: 841.5 | O20: 120BN | P20: 118
A21: 20 | B21: 122BN | C21: 2025122 | D21: B | E21: 1147 | G21: 2025022 | H21: 85 | I21: 719 | K21: 402 | O21: 121AN | P21: empty
A22: 21 | B22: 123AN | C22: 2025123 | D22: A | E22: 0 | G22: 2025023 | H22: 2790 | I22: 888 | K22: 1839 | O22: 121BN | P22: empty
A23: 22 | B23: 123BN | C23: 2025123 | D23: B | E23: 0 | G23: 2025024 | H23: 2113 | I23: 675 | K23: 1394 | O23: 122AN | P23: 2650
A24: 23 | B24: 124AN | C24: 2025124 | D24: A | E24: 2564 | G24: 2025025 | H24: 2171 | I24: 933 | K24: 1552 | O24: 122BN | P24: 1147
A25: 24 | B25: 124BN | C25: 2025124 | D25: B | E25: 2102 | G25: 2025026 | H25: 0 | I25: 0 | K25: 0 | O25: 123AN | P25: empty
A26: 25 | B26: 125AN | C26: 2025125 | D26: A | E26: 1891 | G26: 2025027 | H26: 39 | I26: 161 | K26: 100 | O26: 123BN | P26: empty
A27: 26 | B27: 125BN | C27: 2025125 | D27: B | E27: 891 | G27: 2025028 | H27: 2715 | I27: 1696 | K27: 2205.5 | O27: 124AN | P27: 2564
A28: 27 | B28: 126AN | C28: 2025126 | D28: A | E28: 2057 | G28: 2025029 | H28: 1294 | I28: 454 | K28: 874 | O28: 124BN | P28: 2102
A29: 28 | B29: 126BN | C29: 2025126 | D29: B | E29: 1686 | G29: 2025030 | H29: 228 | I29: 191 | K29: 209.5 | O29: 125AN | P29: 1891
A30: 29 | B30: 127AN | C30: 2025127 | D30: A | E30: 926 | G30: 2025031 | H30: 0 | I30: 0 | K30: 0 | O30: 125BN | P30: 891
A31: 30 | B31: 127BN | C31: 2025127 | D31: B | E31: 1187 | G31: 2025034 | H31: 0 | I31: 0 | K31: 0 | O31: 126AN | P31: 2057
A32: 31 | B32: 128AN | C32: 2025128 | D32: A | E32: 2434 | G32: 2025035 | H32: 206.02 | I32: 212.4 | K32: 209.21 | O32: 126BN | P32: 1686
A33: 32 | B33: 128BN | C33: 2025128 | D33: B | E33: 1076 | G33: 2025036 | H33: 645 | I33: 607 | K33: 626 | O33: 127AN | P33: 926
A34: 33 | B34: 12A | C34: 2025012 | D34: A | E34: 0 | G34: 2025037 | H34: 1871 | I34: 1585 | K34: 1728 | O34: 127BN | P34: 1187
A35: 34 | B35: 12B | C35: 2025012 | D35: B | E35: 0 | G35: 2025038 | H35: 1642 | I35: 1381 | K35: 1511.5 | O35: 128AN | P35: 2434
A36: 35 | B36: 130A | C36: 2025130 | D36: A | E36: 0 | G36: 2025040 | H36: 0 | I36: 0 | K36: 0 | O36: 128BN | P36: 1076
A37: 36 | B37: 130BN | C37: 2025130 | D37: B | E37: 125 | G37: 2025081 | H37: 2745 | I37: 1244 | K37: 1994.5 | O37: 12A | P37: empty
A38: 37 | B38: 132AN | C38: 2025132 | D38: A | E38: 821 | G38: 2025082 | H38: 400 | I38: 338 | K38: 369 | O38: 12B | P38: empty
A39: 38 | B39: 132BN | C39: 2025132 | D39: B | E39: 561 | G39: 2025084 | H39: 1514 | I39: 556 | K39: 1035 | O39: 130A | P39: empty
A40: 39 | B40: 133AN | C40: 2025133 | D40: A | E40: 951 | G40: 2025085 | H40: 2566 | I40: 1512 | K40: 2039 | O40: 130BN | P40: 125
...

Sheet Feuil3
